Workbook

Sheet Priorización
A1: ranking | B1: cve_mun | C1: municipio | D1: pob_2024 | E1: dm2_cualquier | F1: dm2_basica | G1: tasa_anual_dm2 | H1: tasa_dm2_basica | I1: pct_dm2_contribuyente | J1: con_erc | K1: razon_erc_dm2 | L1: con_hta | M1: con_obesidad | N1: avpp_total | O1: avpp_prom | P1: n_inegi | Q1: edad_prom | R1: pct_mujer | S1: pct_sin_escol | T1: pct_sin_derecho | U1: pct_muere_hogar | V1: distancia_gdl_km | W1: total_atencion | X1: primer_nivel | Y1: segundo_nivel | Z1: tercer_nivel | AA1: unidades_x100k | AB1: enigh_hogares | AC1: enigh_ingreso | AD1: enigh_vulnerabilidad | AE1: enigh_internet | AF1: enigh_gasto_salud | AG1: indice_priorizacion | AH1: enigh_cobertura | AI1: norm_tasa_dm2 | AJ1: norm_avpp_total | AK1: norm_avpp_prom | AL1: norm_sin_escol | AM1: norm_sin_derecho | AN1: norm_ingreso_inv | AO1: norm_vulnerabilidad | AP1: norm_internet_inv | AQ1: norm_distancia | AR1: norm_sin_2do | AS1: norm_densidad | AT1: norm_erc_dm2 | AU1: norm_contrib | AV1: D1 | AW1: D2 | AX1: D3 | AY1: D4 | AZ1: D5 | BA1: índice final
B2: 14092 | C2: Teocuitatlán de Corona | D2: 11767 | E2: 203 | F2: 72 | G2: 49.1 | H2: 104.4 | I2: 64.5 | J2: 42 | K2: 0.21 | L2: 102 | M2: 1 | N2: 327.85798 | O2: 6.56 | P2: 50 | Q2: 73.586207 | R2: 44.33 | S2: 47.78 | T2: 67 | U2: 66.01 | V2: 85 | W2: 4 | X2: 4 | Y2: 0 | Z2: 0 | AA2: 34 | AB2: 22 | AC2: 32106.66 | AD2: 0.45 | AE2: 0 | AF2: 1.91 | AG2: =AV2+AW2+AX2+AY2+AZ2 -> 0.57156282 | AH2: ✓ datos directos | AI2: =(G2-MIN($G$2:$G$126))/(MAX($G$2:$G$126)-MIN($G$2:$G$126)) -> 1 | AJ2: =(N2-MIN($N$2:$N$126))/(MAX($N$2:$N$126)-MIN($N$2:$N$126)) -> 0.0069149391 | AK2: =(O2-MIN($O$2:$O$126))/(MAX($O$2:$O$126)-MIN($O$2:$O$126)) -> 0.31953239 | AL2: =(S2-MIN($S$2:$S$126))/(MAX($S$2:$S$126)-MIN($S$2:$S$126)) -> 0.86708566 | AM2: =(T2-MIN($T$2:$T$126))/(MAX($T$2:$T$126)-MIN($T$2:$T$126)) -> 0.68803111 | AN2: =1-(AC2-MIN($AC$2:$AC$126))/(MAX($AC$2:$AC$126)-MIN($AC$2:$AC$126)) -> 0.82998799 | AO2: =(AD2-MIN($AD$2:$AD$126))/(MAX($AD$2:$AD$126)-MIN($AD$2:$AD$126)) -> 0.26946108 | AP2: =1-(AE2-MIN($AE$2:$AE$126))/(MAX($AE$2:$AE$126)-MIN($AE$2:$AE$126)) -> 1 | AQ2: =(V2-MIN($V$2:$V$126))/(MAX($V$2:$V$126)-MIN($V$2:$V$126)) -> 0.23611111 | AR2: =1-(Y2-MIN($Y$2:$Y$126))/(MAX($Y$2:$Y$126)-MIN($Y$2:$Y$126)) -> 1 | AS2: =1-(AA2-MIN($AA$2:$AA$126))/(MAX($AA$2:$AA$126)-MIN($AA$2:$AA$126)) -> 0.772612 | AT2: =(K2-MIN($K$2:$K$126))/(MAX($K$2:$K$126)-MIN($K$2:$K$126)) -> 0.48484848 | AU2: =(L2-MIN($L$2:$L$126))/(MAX($L$2:$L$126)-MIN($L$2:$L$126)) -> 0.013121925 | AV2: =(AI2*(Tablero!$B$5/100)+AJ2*(Tablero!$B$6/100))*(Tablero!$B$4/100) -> 0.15069149 | AW2: =(AK2*(Tablero!$B$8/100))*(Tablero!$B$7/100) -> 0.079883098 | AX2: =(AL2*(Tablero!$B$10/100)+AM2*(Tablero!$B$11/100)+AN2*(Tablero!$B$12/100)+AO2*(Tablero!$B$13/100)+AP2*(Tablero!$B$14/100))*(Tablero!$B$9/100) -> 0.16061256 | AY2: =(AQ2*(Tablero!$B$16/100)+AR2*(Tablero!$B$17/100)+AS2*(Tablero!$B$18/100))*(Tablero!$B$15/100) -> 0.16792641 | AZ2: =(AT2*(Tablero!$B$20/100)+AU2*(Tablero!$B$21/100))*(Tablero!$B$19/100) -> 0.01244926
B3: 14060 | C3: Mexticacán | D3: 5533 | E3: 66 | F3: 18 | G3: 33.6 | H3: 54.9 | I3: 72.7 | J3: 10 | K3: 0.15 | L3: 26 | M3: 0 | N3: 60.412908 | O3: 5.49 | P3: 11 | Q3: 75.060606 | R3: 62.12 | S3: 48.48 | T3: 78.79 | U3: 65.15 | V3: 345 | W3: 1 | X3: 1 | Y3: 0 | Z3: 0 | AA3: 18.1 | AB3: 20 | AC3: 42437.84 | AD3: 0 | AE3: 30 | AF3: 2.49 | AG3: =AV3+AW3+AX3+AY3+AZ3 -> 0.55318995 | AH3: ✓ datos directos | AI3: =(G3-MIN($G$2:$G$126))/(MAX($G$2:$G$126)-MIN($G$2:$G$126)) -> 0.63615023 | AJ3: =(N3-MIN($N$2:$N$126))/(MAX($N$2:$N$126)-MIN($N$2:$N$126)) -> 0.0012741846 | AK3: =(O3-MIN($O$2:$O$126))/(MAX($O$2:$O$126)-MIN($O$2:$O$126)) -> 0.26741354 | AL3: =(S3-MIN($S$2:$S$126))/(MAX($S$2:$S$126)-MIN($S$2:$S$126)) -> 0.88337989 | AM3: =(T3-MIN($T$2:$T$126))/(MAX($T$2:$T$126)-MIN($T$2:$T$126)) -> 0.85784243 | AN3: =1-(AC3-MIN($AC$2:$AC$126))/(MAX($AC$2:$AC$126)-MIN($AC$2:$AC$126)) -> 0.72478174 | AO3: =(AD3-MIN($AD$2:$AD$126))/(MAX($AD$2:$AD$126)-MIN($AD$2:$AD$126)) -> 0 | AP3: =1-(AE3-MIN($AE$2:$AE$126))/(MAX($AE$2:$AE$126)-MIN($AE$2:$AE$126)) -> 0.7 | AQ3: =(V3-MIN($V$2:$V$126))/(MAX($V$2:$V$126)-MIN($V$2:$V$126)) -> 0.95833333 | AR3: =1-(Y3-MIN($Y$2:$Y$126))/(MAX($Y$2:$Y$126)-MIN($Y$2:$Y$126)) -> 1 | AS3: =1-(AA3-MIN($AA$2:$AA$126))/(MAX($AA$2:$AA$126)-MIN($AA$2:$AA$126)) -> 0.90701606 | AT3: =(K3-MIN($K$2:$K$126))/(MAX($K$2:$K$126)-MIN($K$2:$K$126)) -> 0.3030303 | AU3: =(L3-MIN($L$2:$L$126))/(MAX($L$2:$L$126)-MIN($L$2:$L$126)) -> 0.0027337343 | AV3: =(AI3*(Tablero!$B$5/100)+AJ3*(Tablero!$B$6/100))*(Tablero!$B$4/100) -> 0.095549954 | AW3: =(AK3*(Tablero!$B$8/100))*(Tablero!$B$7/100) -> 0.066853385 | AX3: =(AL3*(Tablero!$B$10/100)+AM3*(Tablero!$B$11/100)+AN3*(Tablero!$B$12/100)+AO3*(Tablero!$B$13/100)+AP3*(Tablero!$B$14/100))*(Tablero!$B$9/100) -> 0.13963378 | AY3: =(AQ3*(Tablero!$B$16/100)+AR3*(Tablero!$B$17/100)+AS3*(Tablero!$B$18/100))*(Tablero!$B$15/100) -> 0.24350873 | AZ3: =(AT3*(Tablero!$B$20/100)+AU3*(Tablero!$B$21/100))*(Tablero!$B$19/100) -> 0.0076441009
B4: 14049 | C4: Jilotlán de los Dolores | D4: 9605 | E4: 50 | F4: 19 | G4: 14.4 | H4: 32.9 | I4: 62 | J4: 11 | K4: 0.22 | L4: 26 | M4: 0 | N4: 109.39065 | O4: 15.63 | P4: 7 | Q4: 68.44 | R4: 32 | S4: 28 | T4: 68 | U4: 50 | V4: 310 | W4: 3 | X4: 3 | Y4: 0 | Z4: 0 | AA4: 31.2 | AB4: 21 | AC4: 27116.98 | AD4: 1.67 | AE4: 4.76 | AF4: 1.24 | AG4: =AV4+AW4+AX4+AY4+AZ4 -> 0.62643129 | AH4: ✓ datos directos | AI4: =(G4-MIN($G$2:$G$126))/(MAX($G$2:$G$126)-MIN($G$2:$G$126)) -> 0.18544601 | AJ4: =(N4-MIN($N$2:$N$126))/(MAX($N$2:$N$126)-MIN($N$2:$N$126)) -> 0.0023071871 | AK4: =(O4-MIN($O$2:$O$126))/(MAX($O$2:$O$126)-MIN($O$2:$O$126)) -> 0.76132489 | AL4: =(S4-MIN($S$2:$S$126))/(MAX($S$2:$S$126)-MIN($S$2:$S$126)) -> 0.40665736 | AM4: =(T4-MIN($T$2:$T$126))/(MAX($T$2:$T$126)-MIN($T$2:$T$126)) -> 0.70243411 | AN4: =1-(AC4-MIN($AC$2:$AC$126))/(MAX($AC$2:$AC$126)-MIN($AC$2:$AC$126)) -> 0.88079976 | AO4: =(AD4-MIN($AD$2:$AD$126))/(MAX($AD$2:$AD$126)-MIN($AD$2:$AD$126)) -> 1 | AP4: =1-(AE4-MIN($AE$2:$AE$126))/(MAX($AE$2:$AE$126)-MIN($AE$2:$AE$126)) -> 0.9524 | AQ4: =(V4-MIN($V$2:$V$126))/(MAX($V$2:$V$126)-MIN($V$2:$V$126)) -> 0.86111111 | AR4: =1-(Y4-MIN($Y$2:$Y$126))/(MAX($Y$2:$Y$126)-MIN($Y$2:$Y$126)) -> 1 | AS4: =1-(AA4-MIN($AA$2:$AA$126))/(MAX($AA$2:$AA$126)-MIN($AA$2:$AA$126)) -> 0.79628064 | AT4: =(K4-MIN($K$2:$K$126))/(MAX($K$2:$K$126)-MIN($K$2:$K$126)) -> 0.51515152 | AU4: =(L4-MIN($L$2:$L$126))/(MAX($L$2:$L$126)-MIN($L$2:$L$126)) -> 0.0027337343 | AV4: =(AI4*(Tablero!$B$5/100)+AJ4*(Tablero!$B$6/100))*(Tablero!$B$4/100) -> 0.02804762 | AW4: =(AK4*(Tablero!$B$8/100))*(Tablero!$B$7/100) -> 0.19033122 | AX4: =(AL4*(Tablero!$B$10/100)+AM4*(Tablero!$B$11/100)+AN4*(Tablero!$B$12/100)+AO4*(Tablero!$B$13/100)+AP4*(Tablero!$B$14/100))*(Tablero!$B$9/100) -> 0.16408719 | AY4: =(AQ4*(Tablero!$B$16/100)+AR4*(Tablero!$B$17/100)+AS4*(Tablero!$B$18/100))*(Tablero!$B$15/100) -> 0.23101813 | AZ4: =(AT4*(Tablero!$B$20/100)+AU4*(Tablero!$B$21/100))*(Tablero!$B$19/100) -> 0.012947131
B5: 14019 | C5: Bolaños | D5: 7148 | E5: 33 | F5: 7 | G5: 12.8 | H5: 16.2 | I5: 78.8 | J5: 5 | K5: 0.15 | L5: 14 | M5: 2 | N5: 20.533503 | O5: 20.53 | P5: 1 | Q5: 72.181818 | R5: 48.48 | S5: 39.39 | T5: 45.45 | U5: 51.52 | V5: 305 | W5: 6 | X5: 6 | Y5: 0 | Z5: 0 | AA5: 83.9 | AC5: 52157.1 | AD5: 0.12 | AE5: 45.83 | AF5: 3.02 | AG5: =AV5+AW5+AX5+AY5+AZ5 -> 0.59170561 | AH5: ~ estimación estatal | AI5: =(G5-MIN($G$2:$G$126))/(MAX($G$2:$G$126)-MIN($G$2:$G$126)) -> 0.14788732 | AJ5: =(N5-MIN($N$2:$N$126))/(MAX($N$2:$N$126)-MIN($N$2:$N$126)) -> 0.00043307754 | AK5: =(O5-MIN($O$2:$O$126))/(MAX($O$2:$O$126)-MIN($O$2:$O$126)) -> 1 | AL5: =(S5-MIN($S$2:$S$126))/(MAX($S$2:$S$126)-MIN($S$2:$S$126)) -> 0.67178771 | AM5: =(T5-MIN($T$2:$T$126))/(MAX($T$2:$T$126)-MIN($T$2:$T$126)) -> 0.37764655 | AN5: =1-(AC5-MIN($AC$2:$AC$126))/(MAX($AC$2:$AC$126)-MIN($AC$2:$AC$126)) -> 0.6258069 | AO5: =(AD5-MIN($AD$2:$AD$126))/(MAX($AD$2:$AD$126)-MIN($AD$2:$AD$126)) -> 0.071856287 | AP5: =1-(AE5-MIN($AE$2:$AE$126))/(MAX($AE$2:$AE$126)-MIN($AE$2:$AE$126)) -> 0.5417 | AQ5: =(V5-MIN($V$2:$V$126))/(MAX($V$2:$V$126)-MIN($V$2:$V$126)) -> 0.84722222 | AR5: =1-(Y5-MIN($Y$2:$Y$126))/(MAX($Y$2:$Y$126)-MIN($Y$2:$Y$126)) -> 1 | AS5: =1-(AA5-MIN($AA$2:$AA$126))/(MAX($AA$2:$AA$126)-MIN($AA$2:$AA$126)) -> 0.35080304 | AT5: =(K5-MIN($K$2:$K$126))/(MAX($K$2:$K$126)-MIN($K$2:$K$126)) -> 0.3030303 | AU5: =(L5-MIN($L$2:$L$126))/(MAX($L$2:$L$126)-MIN($L$2:$L$126)) -> 0.0010934937 | AV5: =(AI5*(Tablero!$B$5/100)+AJ5*(Tablero!$B$6/100))*(Tablero!$B$4/100) -> 0.022226406 | AW5: =(AK5*(Tablero!$B$8/100))*(Tablero!$B$7/100) -> 0.25 | AX5: =(AL5*(Tablero!$B$10/100)+AM5*(Tablero!$B$11/100)+AN5*(Tablero!$B$12/100)+AO5*(Tablero!$B$13/100)+AP5*(Tablero!$B$14/100))*(Tablero!$B$9/100) -> 0.093383811 | AY5: =(AQ5*(Tablero!$B$16/100)+AR5*(Tablero!$B$17/100)+AS5*(Tablero!$B$18/100))*(Tablero!$B$15/100) -> 0.2184923 | AZ5: =(AT5*(Tablero!$B$20/100)+AU5*(Tablero!$B$21/100))*(Tablero!$B$19/100) -> 0.0076030949
B6: 14017 | C6: Ayutla | D6: 13337 | E6: 138 | F6: 66 | G6: 29 | H6: 83.3 | I6: 52.2 | J6: 52 | K6: 0.38 | L6: 54 | M6: 4 | N6: 285.81305 | O6: 7.52 | P6: 38 | Q6: 71.282609 | R6: 44.93 | S6: 35.51 | T6: 64.49 | U6: 47.83 | V6: 170 | W6: 5 | X6: 5 | Y6: 0 | Z6: 0 | AA6: 37.5 | AB6: 18 | AC6: 23706.66 | AD6: 1.11 | AE6: 0 | AF6: 1.16 | AG6: =AV6+AW6+AX6+AY6+AZ6 -> 0.54970955 | AH6: ✓ datos directos | AI6: =(G6-MIN($G$2:$G$126))/(MAX($G$2:$G$126)-MIN($G$2:$G$126)) -> 0.52816901 | AJ6: =(N6-MIN($N$2:$N$126))/(MAX($N$2:$N$126)-MIN($N$2:$N$126)) -> 0.0060281585 | AK6: =(O6-MIN($O$2:$O$126))/(MAX($O$2:$O$126)-MIN($O$2:$O$126)) -> 0.36629323 | AL6: =(S6-MIN($S$2:$S$126))/(MAX($S$2:$S$126)-MIN($S$2:$S$126)) -> 0.58147114 | AM6: =(T6-MIN($T$2:$T$126))/(MAX($T$2:$T$126)-MIN($T$2:$T$126)) -> 0.65187959 | AN6: =1-(AC6-MIN($AC$2:$AC$126))/(MAX($AC$2:$AC$126)-MIN($AC$2:$AC$126)) -> 0.91552832 | AO6: =(AD6-MIN($AD$2:$AD$126))/(MAX($AD$2:$AD$126)-MIN($AD$2:$AD$126)) -> 0.66467066 | AP6: =1-(AE6-MIN($AE$2:$AE$126))/(MAX($AE$2:$AE$126)-MIN($AE$2:$AE$126)) -> 1 | AQ6: =(V6-MIN($V$2:$V$126))/(MAX($V$2:$V$126)-MIN($V$2:$V$126)) -> 0.47222222 | AR6: =1-(Y6-MIN($Y$2:$Y$126))/(MAX($Y$2:$Y$126)-MIN($Y$2:$Y$126)) -> 1 | AS6: =1-(AA6-MIN($AA$2:$AA$126))/(MAX($AA$2:$AA$126)-MIN($AA$2:$AA$126)) -> 0.7430262 | AT6: =(K6-MIN($K$2:$K$126))/(MAX($K$2:$K$126)-MIN($K$2:$K$126)) -> 1 | AU6: =(L6-MIN($L$2:$L$126))/(MAX($L$2:$L$126)-MIN($L$2:$L$126)) -> 0.0065609623 | AV6: =(AI6*(Tablero!$B$5/100)+AJ6*(Tablero!$B$6/100))*(Tablero!$B$4/100) -> 0.079828168 | AW6: =(AK6*(Tablero!$B$8/100))*(Tablero!$B$7/100) -> 0.091573307 | AX6: =(AL6*(Tablero!$B$10/100)+AM6*(Tablero!$B$11/100)+AN6*(Tablero!$B$12/100)+AO6*(Tablero!$B$13/100)+AP6*(Tablero!$B$14/100))*(Tablero!$B$9/100) -> 0.16234618 | AY6: =(AQ6*(Tablero!$B$16/100)+AR6*(Tablero!$B$17/100)+AS6*(Tablero!$B$18/100))*(Tablero!$B$15/100) -> 0.19079788 | AZ6: =(AT6*(Tablero!$B$20/100)+AU6*(Tablero!$B$21/100))*(Tablero!$B$19/100) -> 0.025164024
B7: 14026 | C7: Concepción de Buenos Aires | D7: 6589 | E7: 81 | F7: 24 | G7: 34.6 | H7: 61.4 | I7: 70.4 | J7: 20 | K7: 0.25 | L7: 34 | M7: 1 | N7: 101.93711 | O7: 6.37 | P7: 16 | Q7: 71.283951 | R7: 43.21 | S7: 37.04 | T7: 66.67 | U7: 67.9 | V7: 175 | W7: 1 | X7: 1 | Y7: 0 | Z7: 0 | AA7: 15.2 | AC7: 52157.1 | AD7: 0.12 | AE7: 45.83 | AF7: 3.02 | AG7: =AV7+AW7+AX7+AY7+AZ7 -> 0.49950229 | AH7: ~ estimación estatal | AI7: =(G7-MIN($G$2:$G$126))/(MAX($G$2:$G$126)-MIN($G$2:$G$126)) -> 0.65962441 | AJ7: =(N7-MIN($N$2:$N$126))/(MAX($N$2:$N$126)-MIN($N$2:$N$126)) -> 0.0021499825 | AK7: =(O7-MIN($O$2:$O$126))/(MAX($O$2:$O$126)-MIN($O$2:$O$126)) -> 0.31027764 | AL7: =(S7-MIN($S$2:$S$126))/(MAX($S$2:$S$126)-MIN($S$2:$S$126)) -> 0.61708566 | AM7: =(T7-MIN($T$2:$T$126))/(MAX($T$2:$T$126)-MIN($T$2:$T$126)) -> 0.68327812 | AN7: =1-(AC7-MIN($AC$2:$AC$126))/(MAX($AC$2:$AC$126)-MIN($AC$2:$AC$126)) -> 0.6258069 | AO7: =(AD7-MIN($AD$2:$AD$126))/(MAX($AD$2:$AD$126)-MIN($AD$2:$AD$126)) -> 0.071856287 | AP7: =1-(AE7-MIN($AE$2:$AE$126))/(MAX($AE$2:$AE$126)-MIN($AE$2:$AE$126)) -> 0.5417 | AQ7: =(V7-MIN($V$2:$V$126))/(MAX($V$2:$V$126)-MIN($V$2:$V$126)) -> 0.48611111 | AR7: =1-(Y7-MIN($Y$2:$Y$126))/(MAX($Y$2:$Y$126)-MIN($Y$2:$Y$126)) -> 1 | AS7: =1-(AA7-MIN($AA$2:$AA$126))/(MAX($AA$2:$AA$126)-MIN($AA$2:$AA$126)) -> 0.93153001 | AT7: =(K7-MIN($K$2:$K$126))/(MAX($K$2:$K$126)-MIN($K$2:$K$126)) -> 0.60606061 | AU7: =(L7-MIN($L$2:$L$126))/(MAX($L$2:$L$126)-MIN($L$2:$L$126)) -> 0.003827228 | AV7: =(AI7*(Tablero!$B$5/100)+AJ7*(Tablero!$B$6/100))*(Tablero!$B$4/100) -> 0.09915866 | AW7: =(AK7*(Tablero!$B$8/100))*(Tablero!$B$7/100) -> 0.077569411 | AX7: =(AL7*(Tablero!$B$10/100)+AM7*(Tablero!$B$11/100)+AN7*(Tablero!$B$12/100)+AO7*(Tablero!$B$13/100)+AP7*(Tablero!$B$14/100))*(Tablero!$B$9/100) -> 0.11062766 | AY7: =(AQ7*(Tablero!$B$16/100)+AR7*(Tablero!$B$17/100)+AS7*(Tablero!$B$18/100))*(Tablero!$B$15/100) -> 0.19689936 | AZ7: =(AT7*(Tablero!$B$20/100)+AU7*(Tablero!$B$21/100))*(Tablero!$B$19/100) -> 0.015247196
B8: 14048 | C8: Jesús María | D8: 19149 | E8: 229 | F8: 95 | G8: 33 | H8: 82.2 | I8: 58.5 | J8: 26 | K8: 0.11 | L8: 118 | M8: 1 | N8: 440.39193 | O8: 7.73 | P8: 57 | Q8: 72.742358 | R8: 55.46 | S8: 46.72 | T8: 62.45 | U8: 62.01 | V8: 210 | W8: 7 | X8: 7 | Y8: 0 | Z8: 0 | AA8: 36.6 | AC8: 52157.1 | AD8: 0.12 | AE8: 45.83 | AF8: 3.02 | AG8: =AV8+AW8+AX8+AY8+AZ8 -> 0.50688395 | AH8: ~ estimación estatal | AI8: =(G8-MIN($G$2:$G$126))/(MAX($G$2:$G$126)-MIN($G$2:$G$126)) -> 0.62206573 | AJ8: =(N8-MIN($N$2:$N$126))/(MAX($N$2:$N$126)-MIN($N$2:$N$126)) -> 0.0092884225 | AK8: =(O8-MIN($O$2:$O$126))/(MAX($O$2:$O$126)-MIN($O$2:$O$126)) -> 0.37652216 | AL8: =(S8-MIN($S$2:$S$126))/(MAX($S$2:$S$126)-MIN($S$2:$S$126)) -> 0.84241155 | AM8: =(T8-MIN($T$2:$T$126))/(MAX($T$2:$T$126)-MIN($T$2:$T$126)) -> 0.62249748 | AN8: =1-(AC8-MIN($AC$2:$AC$126))/(MAX($AC$2:$AC$126)-MIN($AC$2:$AC$126)) -> 0.6258069 | AO8: =(AD8-MIN($AD$2:$AD$126))/(MAX($AD$2:$AD$126)-MIN($AD$2:$AD$126)) -> 0.071856287 | AP8: =1-(AE8-MIN($AE$2:$AE$126))/(MAX($AE$2:$AE$126)-MIN($AE$2:$AE$126)) -> 0.5417 | AQ8: =(V8-MIN($V$2:$V$126))/(MAX($V$2:$V$126)-MIN($V$2:$V$126)) -> 0.58333333 | AR8: =1-(Y8-MIN($Y$2:$Y$126))/(MAX($Y$2:$Y$126)-MIN($Y$2:$Y$126)) -> 1 | AS8: =1-(AA8-MIN($AA$2:$AA$126))/(MAX($AA$2:$AA$126)-MIN($AA$2:$AA$126)) -> 0.75063398 | AT8: =(K8-MIN($K$2:$K$126))/(MAX($K$2:$K$126)-MIN($K$2:$K$126)) -> 0.18181818 | AU8: =(L8-MIN($L$2:$L$126))/(MAX($L$2:$L$126)-MIN($L$2:$L$126)) -> 0.015308912 | AV8: =(AI8*(Tablero!$B$5/100)+AJ8*(Tablero!$B$6/100))*(Tablero!$B$4/100) -> 0.094238701 | AW8: =(AK8*(Tablero!$B$8/100))*(Tablero!$B$7/100) -> 0.094130541 | AX8: =(AL8*(Tablero!$B$10/100)+AM8*(Tablero!$B$11/100)+AN8*(Tablero!$B$12/100)+AO8*(Tablero!$B$13/100)+AP8*(Tablero!$B$14/100))*(Tablero!$B$9/100) -> 0.11148734 | AY8: =(AQ8*(Tablero!$B$16/100)+AR8*(Tablero!$B$17/100)+AS8*(Tablero!$B$18/100))*(Tablero!$B$15/100) -> 0.20209918 | AZ8: =(AT8*(Tablero!$B$20/100)+AU8*(Tablero!$B$21/100))*(Tablero!$B$19/100) -> 0.0049281773
B9: 14115 | C9: Villa Guerrero | D9: 5239 | E9: 49 | F9: 12 | G9: 25.2 | H9: 37.1 | I9: 75.5 | J9: 9 | K9: 0.18 | L9: 18 | M9: 0 | N9: 54.925703 | O9: 9.15 | P9: 6 | Q9: 73.408163 | R9: 53.06 | S9: 48.98 | T9: 77.55 | U9: 71.43 | V9: 225 | W9: 3 | X9: 3 | Y9: 0 | Z9: 0 | AA9: 57.3 | AB9: 20 | AC9: 47054.63 | AD9: 0.1 | AE9: 50 | AF9: 5.46 | AG9: =AV9+AW9+AX9+AY9+AZ9 -> 0.51221638 | AH9: ✓ datos directos | AI9: =(G9-MIN($G$2:$G$126))/(MAX($G$2:$G$126)-MIN($G$2:$G$126)) -> 0.43896714 | AJ9: =(N9-MIN($N$2:$N$126))/(MAX($N$2:$N$126)-MIN($N$2:$N$126)) -> 0.0011584525 | AK9: =(O9-MIN($O$2:$O$126))/(MAX($O$2:$O$126)-MIN($O$2:$O$126)) -> 0.44568924 | AL9: =(S9-MIN($S$2:$S$126))/(MAX($S$2:$S$126)-MIN($S$2:$S$126)) -> 0.89501862 | AM9: =(T9-MIN($T$2:$T$126))/(MAX($T$2:$T$126)-MIN($T$2:$T$126)) -> 0.83998272 | AN9: =1-(AC9-MIN($AC$2:$AC$126))/(MAX($AC$2:$AC$126)-MIN($AC$2:$AC$126)) -> 0.67776725 | AO9: =(AD9-MIN($AD$2:$AD$126))/(MAX($AD$2:$AD$126)-MIN($AD$2:$AD$126)) -> 0.05988024 | AP9: =1-(AE9-MIN($AE$2:$AE$126))/(MAX($AE$2:$AE$126)-MIN($AE$2:$AE$126)) -> 0.5 | AQ9: =(V9-MIN($V$2:$V$126))/(MAX($V$2:$V$126)-MIN($V$2:$V$126)) -> 0.625 | AR9: =1-(Y9-MIN($Y$2:$Y$126))/(MAX($Y$2:$Y$126)-MIN($Y$2:$Y$126)) -> 1 | AS9: =1-(AA9-MIN($AA$2:$AA$126))/(MAX($AA$2:$AA$126)-MIN($AA$2:$AA$126)) -> 0.57565511 | AT9: =(K9-MIN($K$2:$K$126))/(MAX($K$2:$K$126)-MIN($K$2:$K$126)) -> 0.39393939 | AU9: =(L9-MIN($L$2:$L$126))/(MAX($L$2:$L$126)-MIN($L$2:$L$126)) -> 0.0016402406 | AV9: =(AI9*(Tablero!$B$5/100)+AJ9*(Tablero!$B$6/100))*(Tablero!$B$4/100) -> 0.065960916 | AW9: =(AK9*(Tablero!$B$8/100))*(Tablero!$B$7/100) -> 0.11142231 | AX9: =(AL9*(Tablero!$B$10/100)+AM9*(Tablero!$B$11/100)+AN9*(Tablero!$B$12/100)+AO9*(Tablero!$B$13/100)+AP9*(Tablero!$B$14/100))*(Tablero!$B$9/100) -> 0.12305229 | AY9: =(AQ9*(Tablero!$B$16/100)+AR9*(Tablero!$B$17/100)+AS9*(Tablero!$B$18/100))*(Tablero!$B$15/100) -> 0.20189138 | AZ9: =(AT9*(Tablero!$B$20/100)+AU9*(Tablero!$B$21/100))*(Tablero!$B$19/100) -> 0.0098894909
B10: 14102 | C10: Tonaya | D10: 5994 | E10: 86 | F10: 13 | G10: 39.7 | H10: 36 | I10: 84.9 | J10: 13 | K10: 0.15 | L10: 35 | M10: 1 | N10: 9.0042852 | O10: 3 | P10: 3 | Q10: 74.139535 | R10: 52.33 | S10: 39.53 | T10: 55.81 | U10: 47.67 | V10: 195 | W10: 1 | X10: 1 | Y10: 0 | Z10: 0 | AA10: 16.7 | AC10: 52157.1 | AD10: 0.12 | AE10: 45.83 | AF10: 3.02 | AG10: =AV10+AW10+AX10+AY10+AZ10 -> 0.46566698 | AH10: ~ estimación estatal | AI10: =(G10-MIN($G$2:$G$126))/(MAX($G$2:$G$126)-MIN($G$2:$G$126)) -> 0.77934272 | AJ10: =(N10-MIN($N$2:$N$126))/(MAX($N$2:$N$126)-MIN($N$2:$N$126)) -> 0.00018991176 | AK10: =(O10-MIN($O$2:$O$126))/(MAX($O$2:$O$126)-MIN($O$2:$O$126)) -> 0.14612762 | AL10: =(S10-MIN($S$2:$S$126))/(MAX($S$2:$S$126)-MIN($S$2:$S$126)) -> 0.67504655 | AM10: =(T10-MIN($T$2:$T$126))/(MAX($T$2:$T$126)-MIN($T$2:$T$126)) -> 0.52686159 | AN10: =1-(AC10-MIN($AC$2:$AC$126))/(MAX($AC$2:$AC$126)-MIN($AC$2:$AC$126)) -> 0.6258069 | AO10: =(AD10-MIN($AD$2:$AD$126))/(MAX($AD$2:$AD$126)-MIN($AD$2:$AD$126)) -> 0.071856287 | AP10: =1-(AE10-MIN($AE$2:$AE$126))/(MAX($AE$2:$AE$126)-MIN($AE$2:$AE$126)) -> 0.5417 | AQ10: =(V10-MIN($V$2:$V$126))/(MAX($V$2:$V$126)-MIN($V$2:$V$126)) -> 0.54166667 | AR10: =1-(Y10-MIN($Y$2:$Y$126))/(MAX($Y$2:$Y$126)-MIN($Y$2:$Y$126)) -> 1 | AS10: =1-(AA10-MIN($AA$2:$AA$126))/(MAX($AA$2:$AA$126)-MIN($AA$2:$AA$126)) -> 0.91885038 | AT10: =(K10-MIN($K$2:$K$126))/(MAX($K$2:$K$126)-MIN($K$2:$K$126)) -> 0.3030303 | AU10: =(L10-MIN($L$2:$L$126))/(MAX($L$2:$L$126)-MIN($L$2:$L$126)) -> 0.0039639147 | AV10: =(AI10*(Tablero!$B$5/100)+AJ10*(Tablero!$B$6/100))*(Tablero!$B$4/100) -> 0.1169204 | AW10: =(AK10*(Tablero!$B$8/100))*(Tablero!$B$7/100) -> 0.036531905 | AX10: =(AL10*(Tablero!$B$10/100)+AM10*(Tablero!$B$11/100)+AN10*(Tablero!$B$12/100)+AO10*(Tablero!$B$13/100)+AP10*(Tablero!$B$14/100))*(Tablero!$B$9/100) -> 0.10240189 | AY10: =(AQ10*(Tablero!$B$16/100)+AR10*(Tablero!$B$17/100)+AS10*(Tablero!$B$18/100))*(Tablero!$B$15/100) -> 0.20213793 | AZ10: =(AT10*(Tablero!$B$20/100)+AU10*(Tablero!$B$21/100))*(Tablero!$B$19/100) -> 0.0076748554
B11: 14104 | C11: Totatiche | D11: 4121 | E11: 52 | F11: 17 | G11: 34.4 | H11: 67.6 | I11: 67.3 | J11: 8 | K11: 0.15 | L11: 24 | M11: 2 | N11: 58.437689 | O11: 6.49 | P11: 9 | Q11: 75.942308 | R11: 48.08 | S11: 28.85 | T11: 67.31 | U11: 75 | V11: 275 | W11: 2 | X11: 2 | Y11: 0 | Z11: 0 | AA11: 48.5 | AC11: 52157.1 | AD11: 0.12 | AE11: 45.83 | AF11: 3.02 | AG11: =AV11+AW11+AX11+AY11+AZ11 -> 0.51003848 | AH11: ~ estimación estatal | AI11: =(G11-MIN($G$2:$G$126))/(MAX($G$2:$G$126)-MIN($G$2:$G$126)) -> 0.65492958 | AJ11: =(N11-MIN($N$2:$N$126))/(MAX($N$2:$N$126)-MIN($N$2:$N$126)) -> 0.0012325247 | AK11: =(O11-MIN($O$2:$O$126))/(MAX($O$2:$O$126)-MIN($O$2:$O$126)) -> 0.31612275 | AL11: =(S11-MIN($S$2:$S$126))/(MAX($S$2:$S$126)-MIN($S$2:$S$126)) -> 0.4264432 | AM11: =(T11-MIN($T$2:$T$126))/(MAX($T$2:$T$126)-MIN($T$2:$T$126)) -> 0.69249604 | AN11: =1-(AC11-MIN($AC$2:$AC$126))/(MAX($AC$2:$AC$126)-MIN($AC$2:$AC$126)) -> 0.6258069 | AO11: =(AD11-MIN($AD$2:$AD$126))/(MAX($AD$2:$AD$126)-MIN($AD$2:$AD$126)) -> 0.071856287 | AP11: =1-(AE11-MIN($AE$2:$AE$126))/(MAX($AE$2:$AE$126)-MIN($AE$2:$AE$126)) -> 0.5417 | AQ11: =(V11-MIN($V$2:$V$126))/(MAX($V$2:$V$126)-MIN($V$2:$V$126)) -> 0.76388889 | AR11: =1-(Y11-MIN($Y$2:$Y$126))/(MAX($Y$2:$Y$126)-MIN($Y$2:$Y$126)) -> 1 | AS11: =1-(AA11-MIN($AA$2:$AA$126))/(MAX($AA$2:$AA$126)-MIN($AA$2:$AA$126)) -> 0.65004227 | AT11: =(K11-MIN($K$2:$K$126))/(MAX($K$2:$K$126)-MIN($K$2:$K$126)) -> 0.3030303 | AU11: =(L11-MIN($L$2:$L$126))/(MAX($L$2:$L$126)-MIN($L$2:$L$126)) -> 0.0024603609 | AV11: =(AI11*(Tablero!$B$5/100)+AJ11*(Tablero!$B$6/100))*(Tablero!$B$4/100) -> 0.098362689 | AW11: =(AK11*(Tablero!$B$8/100))*(Tablero!$B$7/100) -> 0.079030687 | AX11: =(AL11*(Tablero!$B$10/100)+AM11*(Tablero!$B$11/100)+AN11*(Tablero!$B$12/100)+AO11*(Tablero!$B$13/100)+AP11*(Tablero!$B$14/100))*(Tablero!$B$9/100) -> 0.10736789 | AY11: =(AQ11*(Tablero!$B$16/100)+AR11*(Tablero!$B$17/100)+AS11*(Tablero!$B$18/100))*(Tablero!$B$15/100) -> 0.21763995 | AZ11: =(AT11*(Tablero!$B$20/100)+AU11*(Tablero!$B$21/100))*(Tablero!$B$19/100) -> 0.0076372666
B12: 14087 | C12: Tecalitlán | D12: 15936 | E12: 187 | F12: 74 | G12: 31.7 | H12: 75.3 | I12: 60.4 | J12: 44 | K12: 0.24 | L12: 102 | M12: 1 | N12: 241.72731 | O12: 7.11 | P12: 34 | Q12: 72.13369 | R12: 51.87 | S12: 37.43 | T12: 52.94 | U12: 50.27 | V12: 220 | W12: 5 | X12: 5 | Y12: 0 | Z12: 0 | AA12: 31.4 | AB12: 23 | AC12: 39447.45 | AD12: 0.09 | AE12: 26.09 | AF12: 3.48 | AG12: =AV12+AW12+AX12+AY12+AZ12 -> 0.51348599 | AH12: ✓ datos directos | AI12: =(G12-MIN($G$2:$G$126))/(MAX($G$2:$G$126)-MIN($G$2:$G$126)) -> 0.5915493 | AJ12: =(N12-MIN($N$2:$N$126))/(MAX($N$2:$N$126)-MIN($N$2:$N$126)) -> 0.0050983345 | AK12: =(O12-MIN($O$2:$O$126))/(MAX($O$2:$O$126)-MIN($O$2:$O$126)) -> 0.34632245 | AL12: =(S12-MIN($S$2:$S$126))/(MAX($S$2:$S$126)-MIN($S$2:$S$126)) -> 0.62616387 | AM12: =(T12-MIN($T$2:$T$126))/(MAX($T$2:$T$126)-MIN($T$2:$T$126)) -> 0.48552499 | AN12: =1-(AC12-MIN($AC$2:$AC$126))/(MAX($AC$2:$AC$126)-MIN($AC$2:$AC$126)) -> 0.755234 | AO12: =(AD12-MIN($AD$2:$AD$126))/(MAX($AD$2:$AD$126)-MIN($AD$2:$AD$126)) -> 0.053892216 | AP12: =1-(AE12-MIN($AE$2:$AE$126))/(MAX($AE$2:$AE$126)-MIN($AE$2:$AE$126)) -> 0.7391 | AQ12: =(V12-MIN($V$2:$V$126))/(MAX($V$2:$V$126)-MIN($V$2:$V$126)) -> 0.61111111 | AR12: =1-(Y12-MIN($Y$2:$Y$126))/(MAX($Y$2:$Y$126)-MIN($Y$2:$Y$126)) -> 1 | AS12: =1-(AA12-MIN($AA$2:$AA$126))/(MAX($AA$2:$AA$126)-MIN($AA$2:$AA$126)) -> 0.79459003 | AT12: =(K12-MIN($K$2:$K$126))/(MAX($K$2:$K$126)-MIN($K$2:$K$126)) -> 0.57575758 | AU12: =(L12-MIN($L$2:$L$126))/(MAX($L$2:$L$126)-MIN($L$2:$L$126)) -> 0.013121925 | AV12: =(AI12*(Tablero!$B$5/100)+AJ12*(Tablero!$B$6/100))*(Tablero!$B$4/100) -> 0.089242228 | AW12: =(AK12*(Tablero!$B$8/100))*(Tablero!$B$7/100) -> 0.086580614 | AX12: =(AL12*(Tablero!$B$10/100)+AM12*(Tablero!$B$11/100)+AN12*(Tablero!$B$12/100)+AO12*(Tablero!$B$13/100)+AP12*(Tablero!$B$14/100))*(Tablero!$B$9/100) -> 0.1169653 | AY12: =(AQ12*(Tablero!$B$16/100)+AR12*(Tablero!$B$17/100)+AS12*(Tablero!$B$18/100))*(Tablero!$B$15/100) -> 0.20597586 | AZ12: =(AT12*(Tablero!$B$20/100)+AU12*(Tablero!$B$21/100))*(Tablero!$B$19/100) -> 0.014721988
B13: 14103 | C13: Tonila | D13: 7709 | E13: 108 | F13: 48 | G13: 38.8 | H13: 103.5 | I13: 55.6 | J13: 32 | K13: 0.3 | L13: 57 | M13: 1 | N13: 188.10697 | O13: 7.23 | P13: 26 | Q13: 70.759259 | R13: 46.3 | S13: 40.74 | T13: 28.7 | U13: 52.78 | V13: 180 | W13: 3 | X13: 3 | Y13: 0 | Z13: 0 | AA13: 38.9 | AC13: 52157.1 | AD13: 0.12 | AE13: 45.83 | AF13: 3.02 | AG13: =AV13+AW13+AX13+AY13+AZ13 -> 0.49410178 | AH13: ~ estimación estatal | AI13: =(G13-MIN($G$2:$G$126))/(MAX($G$2:$G$126)-MIN($G$2:$G$126)) -> 0.75821596 | AJ13: =(N13-MIN($N$2:$N$126))/(MAX($N$2:$N$126)-MIN($N$2:$N$126)) -> 0.0039674138 | AK13: =(O13-MIN($O$2:$O$126))/(MAX($O$2:$O$126)-MIN($O$2:$O$126)) -> 0.35216756 | AL13: =(S13-MIN($S$2:$S$126))/(MAX($S$2:$S$126)-MIN($S$2:$S$126)) -> 0.70321229 | AM13: =(T13-MIN($T$2:$T$126))/(MAX($T$2:$T$126)-MIN($T$2:$T$126)) -> 0.13639637 | AN13: =1-(AC13-MIN($AC$2:$AC$126))/(MAX($AC$2:$AC$126)-MIN($AC$2:$AC$126)) -> 0.6258069 | AO13: =(AD13-MIN($AD$2:$AD$126))/(MAX($AD$2:$AD$126)-MIN($AD$2:$AD$126)) -> 0.071856287 | AP13: =1-(AE13-MIN($AE$2:$AE$126))/(MAX($AE$2:$AE$126)-MIN($AE$2:$AE$126)) -> 0.5417 | AQ13: =(V13-MIN($V$2:$V$126))/(MAX($V$2:$V$126)-MIN($V$2:$V$126)) -> 0.5 | AR13: =1-(Y13-MIN($Y$2:$Y$126))/(MAX($Y$2:$Y$126)-MIN($Y$2:$Y$126)) -> 1 | AS13: =1-(AA13-MIN($AA$2:$AA$126))/(MAX($AA$2:$AA$126)-MIN($AA$2:$AA$126)) -> 0.73119189 | AT13: =(K13-MIN($K$2:$K$126))/(MAX($K$2:$K$126)-MIN($K$2:$K$126)) -> 0.75757576 | AU13: =(L13-MIN($L$2:$L$126))/(MAX($L$2:$L$126)-MIN($L$2:$L$126)) -> 0.0069710224 | AV13: =(AI13*(Tablero!$B$5/100)+AJ13*(Tablero!$B$6/100))*(Tablero!$B$4/100) -> 0.11412914 | AW13: =(AK13*(Tablero!$B$8/100))*(Tablero!$B$7/100) -> 0.08804189 | AX13: =(AL13*(Tablero!$B$10/100)+AM13*(Tablero!$B$11/100)+AN13*(Tablero!$B$12/100)+AO13*(Tablero!$B$13/100)+AP13*(Tablero!$B$14/100))*(Tablero!$B$9/100) -> 0.079537292 | AY13: =(AQ13*(Tablero!$B$16/100)+AR13*(Tablero!$B$17/100)+AS13*(Tablero!$B$18/100))*(Tablero!$B$15/100) -> 0.1932798 | AZ13: =(AT13*(Tablero!$B$20/100)+AU13*(Tablero!$B$21/100))*(Tablero!$B$19/100) -> 0.019113669
B14: 14089 | C14: Techaluta de Montenegro | D14: 4355 | E14: 49 | F14: 20 | G14: 32.1 | H14: 78.6 | I14: 59.2 | J14: 16 | K14: 0.33 | L14: 19 | M14: 3 | N14: 62.061831 | O14: 5.64 | P14: 11 | Q14: 75.428571 | R14: 57.14 | S14: 48.98 | T14: 57.14 | U14: 59.18 | V14: 190 | W14: 2 | X14: 2 | Y14: 0 | Z14: 0 | AA14: 45.9 | AB14: 40 | AC14: 57894.95 | AD14: 0.1 | AE14: 32.5 | AF14: 4.07 | AG14: =AV14+AW14+AX14+AY14+AZ14 -> 0.49199311 | AH14: ✓ datos directos | AI14: =(G14-MIN($G$2:$G$126))/(MAX($G$2:$G$126)-MIN($G$2:$G$126)) -> 0.60093897 | AJ14: =(N14-MIN($N$2:$N$126))/(MAX($N$2:$N$126)-MIN($N$2:$N$126)) -> 0.0013089625 | AK14: =(O14-MIN($O$2:$O$126))/(MAX($O$2:$O$126)-MIN($O$2:$O$126)) -> 0.27471992 | AL14: =(S14-MIN($S$2:$S$126))/(MAX($S$2:$S$126)-MIN($S$2:$S$126)) -> 0.89501862 | AM14: =(T14-MIN($T$2:$T$126))/(MAX($T$2:$T$126)-MIN($T$2:$T$126)) -> 0.54601757 | AN14: =1-(AC14-MIN($AC$2:$AC$126))/(MAX($AC$2:$AC$126)-MIN($AC$2:$AC$126)) -> 0.56737624 | AO14: =(AD14-MIN($AD$2:$AD$126))/(MAX($AD$2:$AD$126)-MIN($AD$2:$AD$126)) -> 0.05988024 | AP14: =1-(AE14-MIN($AE$2:$AE$126))/(MAX($AE$2:$AE$126)-MIN($AE$2:$AE$126)) -> 0.675 | AQ14: =(V14-MIN($V$2:$V$126))/(MAX($V$2:$V$126)-MIN($V$2:$V$126)) -> 0.52777778 | AR14: =1-(Y14-MIN($Y$2:$Y$126))/(MAX($Y$2:$Y$126)-MIN($Y$2:$Y$126)) -> 1 | AS14: =1-(AA14-MIN($AA$2:$AA$126))/(MAX($AA$2:$AA$126)-MIN($AA$2:$AA$126)) -> 0.67202029 | AT14: =(K14-MIN($K$2:$K$126))/(MAX($K$2:$K$126)-MIN($K$2:$K$126)) -> 0.84848485 | AU14: =(L14-MIN($L$2:$L$126))/(MAX($L$2:$L$126)-MIN($L$2:$L$126)) -> 0.0017769273 | AV14: =(AI14*(Tablero!$B$5/100)+AJ14*(Tablero!$B$6/100))*(Tablero!$B$4/100) -> 0.090271741 | AW14: =(AK14*(Tablero!$B$8/100))*(Tablero!$B$7/100) -> 0.068679981 | AX14: =(AL14*(Tablero!$B$10/100)+AM14*(Tablero!$B$11/100)+AN14*(Tablero!$B$12/100)+AO14*(Tablero!$B$13/100)+AP14*(Tablero!$B$14/100))*(Tablero!$B$9/100) -> 0.11720656 | AY14: =(AQ14*(Tablero!$B$16/100)+AR14*(Tablero!$B$17/100)+AS14*(Tablero!$B$18/100))*(Tablero!$B$15/100) -> 0.19457828 | AZ14: =(AT14*(Tablero!$B$20/100)+AU14*(Tablero!$B$21/100))*(Tablero!$B$19/100) -> 0.021256544
B15: 14014 | C15: Atoyac | D15: 9122 | E15: 117 | F15: 36 | G15: 36.2 | H15: 66.9 | I15: 69.2 | J15: 33 | K15: 0.28 | L15: 54 | M15: 0 | N15: 134.89297 | O15: 5.86 | P15: 23 | Q15: 73.726496 | R15: 48.72 | S15: 38.46 | T15: 64.96 | U15: 63.25 | V15: 80 | W15: 3 | X15: 3 | Y15: 0 | Z15: 0 | AA15: 32.9 | AB15: 23 | AC15: 50833.81 | AD15: 0.04 | AE15: 43.48 | AF15: 1.53 | AG15: =AV15+AW15+AX15+AY15+AZ15 -> 0.47158163 | AH15: ✓ datos directos | AI15: =(G15-MIN($G$2:$G$126))/(MAX($G$2:$G$126)-MIN($G$2:$G$126)) -> 0.6971831 | AJ15: =(N15-MIN($N$2:$N$126))/(MAX($N$2:$N$126)-MIN($N$2:$N$126)) -> 0.0028450633 | AK15: =(O15-MIN($O$2:$O$126))/(MAX($O$2:$O$126)-MIN($O$2:$O$126)) -> 0.28543595 | AL15: =(S15-MIN($S$2:$S$126))/(MAX($S$2:$S$126)-MIN($S$2:$S$126)) -> 0.65013966 | AM15: =(T15-MIN($T$2:$T$126))/(MAX($T$2:$T$126)-MIN($T$2:$T$126)) -> 0.658649 | AN15: =1-(AC15-MIN($AC$2:$AC$126))/(MAX($AC$2:$AC$126)-MIN($AC$2:$AC$126)) -> 0.63928246 | AO15: =(AD15-MIN($AD$2:$AD$126))/(MAX($AD$2:$AD$126)-MIN($AD$2:$AD$126)) -> 0.023952096 | AP15: =1-(AE15-MIN($AE$2:$AE$126))/(MAX($AE$2:$AE$126)-MIN($AE$2:$AE$126)) -> 0.5652 | AQ15: =(V15-MIN($V$2:$V$126))/(MAX($V$2:$V$126)-MIN($V$2:$V$126)) -> 0.22222222 | AR15: =1-(Y15-MIN($Y$2:$Y$126))/(MAX($Y$2:$Y$126)-MIN($Y$2:$Y$126)) -> 1 | AS15: =1-(AA15-MIN($AA$2:$AA$126))/(MAX($AA$2:$AA$126)-MIN($AA$2:$AA$126)) -> 0.7819104 | AT15: =(K15-MIN($K$2:$K$126))/(MAX($K$2:$K$126)-MIN($K$2:$K$126)) -> 0.6969697 | AU15: =(L15-MIN($L$2:$L$126))/(MAX($L$2:$L$126)-MIN($L$2:$L$126)) -> 0.0065609623 | AV15: =(AI15*(Tablero!$B$5/100)+AJ15*(Tablero!$B$6/100))*(Tablero!$B$4/100) -> 0.10486197 | AW15: =(AK15*(Tablero!$B$8/100))*(Tablero!$B$7/100) -> 0.071358987 | AX15: =(AL15*(Tablero!$B$10/100)+AM15*(Tablero!$B$11/100)+AN15*(Tablero!$B$12/100)+AO15*(Tablero!$B$13/100)+AP15*(Tablero!$B$14/100))*(Tablero!$B$9/100) -> 0.11100242 | AY15: =(AQ15*(Tablero!$B$16/100)+AR15*(Tablero!$B$17/100)+AS15*(Tablero!$B$18/100))*(Tablero!$B$15/100) -> 0.16676998 | AZ15: =(AT15*(Tablero!$B$20/100)+AU15*(Tablero!$B$21/100))*(Tablero!$B$19/100) -> 0.017588266
B16: 14011 | C16: Atengo | D16: 5743 | E16: 47 | F16: 20 | G16: 22.8 | H16: 58.3 | I16: 57.4 | J16: 10 | K16: 0.21 | L16: 26 | M16: 0 | N16: 148.73878 | O16: 8.75 | P16: 17 | Q16: 69.489362 | R16: 46.81 | S16: 48.94 | T16: 59.57 | U16: 72.34 | V16: 195 | W16: 2 | X16: 2 | Y16: 0 | Z16: 0 | AA16: 34.8 | AB16: 93 | AC16: 41113.71 | AD16: 0.16 | AE16: 38.71 | AF16: 4.85 | AG16: =AV16+AW16+AX16+AY16+AZ16 -> 0.49321817 | AH16: ✓ datos directos | AI16: =(G16-MIN($G$2:$G$126))/(MAX($G$2:$G$126)-MIN($G$2:$G$126)) -> 0.38262911 | AJ16: =(N16-MIN($N$2:$N$126))/(MAX($N$2:$N$126)-MIN($N$2:$N$126)) -> 0.003137089 | AK16: =(O16-MIN($O$2:$O$126))/(MAX($O$2:$O$126)-MIN($O$2:$O$126)) -> 0.42620555 | AL16: =(S16-MIN($S$2:$S$126))/(MAX($S$2:$S$126)-MIN($S$2:$S$126)) -> 0.89408752 | AM16: =(T16-MIN($T$2:$T$126))/(MAX($T$2:$T$126)-MIN($T$2:$T$126)) -> 0.58101685 | AN16: =1-(AC16-MIN($AC$2:$AC$126))/(MAX($AC$2:$AC$126)-MIN($AC$2:$AC$126)) -> 0.73826585 | AO16: =(AD16-MIN($AD$2:$AD$126))/(MAX($AD$2:$AD$126)-MIN($AD$2:$AD$126)) -> 0.095808383 | AP16: =1-(AE16-MIN($AE$2:$AE$126))/(MAX($AE$2:$AE$126)-MIN($AE$2:$AE$126)) -> 0.6129 | AQ16: =(V16-MIN($V$2:$V$126))/(MAX($V$2:$V$126)-MIN($V$2:$V$126)) -> 0.54166667 | AR16: =1-(Y16-MIN($Y$2:$Y$126))/(MAX($Y$2:$Y$126)-MIN($Y$2:$Y$126)) -> 1 | AS16: =1-(AA16-MIN($AA$2:$AA$126))/(MAX($AA$2:$AA$126)-MIN($AA$2:$AA$126)) -> 0.76584954 | AT16: =(K16-MIN($K$2:$K$126))/(MAX($K$2:$K$126)-MIN($K$2:$K$126)) -> 0.48484848 | AU16: =(L16-MIN($L$2:$L$126))/(MAX($L$2:$L$126)-MIN($L$2:$L$126)) -> 0.0027337343 | AV16: =(AI16*(Tablero!$B$5/100)+AJ16*(Tablero!$B$6/100))*(Tablero!$B$4/100) -> 0.057708075 | AW16: =(AK16*(Tablero!$B$8/100))*(Tablero!$B$7/100) -> 0.10655139 | AX16: =(AL16*(Tablero!$B$10/100)+AM16*(Tablero!$B$11/100)+AN16*(Tablero!$B$12/100)+AO16*(Tablero!$B$13/100)+AP16*(Tablero!$B$14/100))*(Tablero!$B$9/100) -> 0.11845625 | AY16: =(AQ16*(Tablero!$B$16/100)+AR16*(Tablero!$B$17/100)+AS16*(Tablero!$B$18/100))*(Tablero!$B$15/100) -> 0.19831291 | AZ16: =(AT16*(Tablero!$B$20/100)+AU16*(Tablero!$B$21/100))*(Tablero!$B$19/100) -> 0.012189555
B17: 14021 | C17: Casimiro Castillo | D17: 20792 | E17: 312 | F17: 124 | G17: 41.4 | H17: 98.8 | I17: 60.3 | J17: 83 | K17: 0.27 | L17: 162 | M17: 5 | N17: 485.74885 | O17: 7.14 | P17: 68 | Q17: 69.810897 | R17: 49.68 | S17: 36.22 | T17: 28.21 | U17: 37.82 | V17: 270 | W17: 7 | X17: 6 | Y17: 1 | Z17: 0 | AA17: 33.7 | AB17: 18 | AC17: 35350.66 | AD17: 0 | AE17: 38.89 | AF17: 0.83 | AG17: =AV17+AW17+AX17+AY17+AZ17 -> 0.53068148 | AH17: ✓ datos directos | AI17: =(G17-MIN($G$2:$G$126))/(MAX($G$2:$G$126)-MIN($G$2:$G$126)) -> 0.81924883 | AJ17: =(N17-MIN($N$2:$N$126))/(MAX($N$2:$N$126)-MIN($N$2:$N$126)) -> 0.010245057 | AK17: =(O17-MIN($O$2:$O$126))/(MAX($O$2:$O$126)-MIN($O$2:$O$126)) -> 0.34778373 | AL17: =(S17-MIN($S$2:$S$126))/(MAX($S$2:$S$126)-MIN($S$2:$S$126)) -> 0.59799814 | AM17: =(T17-MIN($T$2:$T$126))/(MAX($T$2:$T$126)-MIN($T$2:$T$126)) -> 0.1293389 | AN17: =1-(AC17-MIN($AC$2:$AC$126))/(MAX($AC$2:$AC$126)-MIN($AC$2:$AC$126)) -> 0.79695314 | AO17: =(AD17-MIN($AD$2:$AD$126))/(MAX($AD$2:$AD$126)-MIN($AD$2:$AD$126)) -> 0 | AP17: =1-(AE17-MIN($AE$2:$AE$126))/(MAX($AE$2:$AE$126)-MIN($AE$2:$AE$126)) -> 0.6111 | AQ17: =(V17-MIN($V$2:$V$126))/(MAX($V$2:$V$126)-MIN($V$2:$V$126)) -> 0.75 | AR17: =1-(Y17-MIN($Y$2:$Y$126))/(MAX($Y$2:$Y$126)-MIN($Y$2:$Y$126)) -> 0.98958333 | AS17: =1-(AA17-MIN($AA$2:$AA$126))/(MAX($AA$2:$AA$126)-MIN($AA$2:$AA$126)) -> 0.77514793 | AT17: =(K17-MIN($K$2:$K$126))/(MAX($K$2:$K$126)-MIN($K$2:$K$126)) -> 0.66666667 | AU17: =(L17-MIN($L$2:$L$126))/(MAX($L$2:$L$126)-MIN($L$2:$L$126)) -> 0.021323127 | AV17: =(AI17*(Tablero!$B$5/100)+AJ17*(Tablero!$B$6/100))*(Tablero!$B$4/100) -> 0.12391183 | AW17: =(AK17*(Tablero!$B$8/100))*(Tablero!$B$7/100) -> 0.086945933 | AX17: =(AL17*(Tablero!$B$10/100)+AM17*(Tablero!$B$11/100)+AN17*(Tablero!$B$12/100)+AO17*(Tablero!$B$13/100)+AP17*(Tablero!$B$14/100))*(Tablero!$B$9/100) -> 0.08454736 | AY17: =(AQ17*(Tablero!$B$16/100)+AR17*(Tablero!$B$17/100)+AS17*(Tablero!$B$18/100))*(Tablero!$B$15/100) -> 0.21807661 | AZ17: =(AT17*(Tablero!$B$20/100)+AU17*(Tablero!$B$21/100))*(Tablero!$B$19/100) -> 0.017199745
B18: 14041 | C18: Huejúcar | D18: 6212 | E18: 54 | F18: 16 | G18: 24.5 | H18: 43.6 | I18: 70.4 | J18: 16 | K18: 0.3 | L18: 24 | M18: 1 | N18: 16.618764 | O18: 2.77 | P18: 6 | Q18: 75.925926 | R18: 42.59 | S18: 51.85 | T18: 61.11 | U18: 61.11 | V18: 285 | W18: 4 | X18: 4 | Y18: 0 | Z18: 0 | AA18: 64.4 | AB18: 21 | AC18: 35735.83 | AD18: 0.76 | AE18: 9.52 | AF18: 1.79 | AG18: =AV18+AW18+AX18+AY18+AZ18 -> 0.48597974 | AH18: ✓ datos directos | AI18: =(G18-MIN($G$2:$G$126))/(MAX($G$2:$G$126)-MIN($G$2:$G$126)) -> 0.42253521 | AJ18: =(N18-MIN($N$2:$N$126))/(MAX($N$2:$N$126)-MIN($N$2:$N$126)) -> 0.00035051074 | AK18: =(O18-MIN($O$2:$O$126))/(MAX($O$2:$O$126)-MIN($O$2:$O$126)) -> 0.1349245 | AL18: =(S18-MIN($S$2:$S$126))/(MAX($S$2:$S$126)-MIN($S$2:$S$126)) -> 0.96182495 | AM18: =(T18-MIN($T$2:$T$126))/(MAX($T$2:$T$126)-MIN($T$2:$T$126)) -> 0.60319747 | AN18: =1-(AC18-MIN($AC$2:$AC$126))/(MAX($AC$2:$AC$126)-MIN($AC$2:$AC$126)) -> 0.79303081 | AO18: =(AD18-MIN($AD$2:$AD$126))/(MAX($AD$2:$AD$126)-MIN($AD$2:$AD$126)) -> 0.45508982 | AP18: =1-(AE18-MIN($AE$2:$AE$126))/(MAX($AE$2:$AE$126)-MIN($AE$2:$AE$126)) -> 0.9048 | AQ18: =(V18-MIN($V$2:$V$126))/(MAX($V$2:$V$126)-MIN($V$2:$V$126)) -> 0.79166667 | AR18: =1-(Y18-MIN($Y$2:$Y$126))/(MAX($Y$2:$Y$126)-MIN($Y$2:$Y$126)) -> 1 | AS18: =1-(AA18-MIN($AA$2:$AA$126))/(MAX($AA$2:$AA$126)-MIN($AA$2:$AA$126)) -> 0.51563821 | AT18: =(K18-MIN($K$2:$K$126))/(MAX($K$2:$K$126)-MIN($K$2:$K$126)) -> 0.75757576 | AU18: =(L18-MIN($L$2:$L$126))/(MAX($L$2:$L$126)-MIN($L$2:$L$126)) -> 0.0024603609 | AV18: =(AI18*(Tablero!$B$5/100)+AJ18*(Tablero!$B$6/100))*(Tablero!$B$4/100) -> 0.063415333 | AW18: =(AK18*(Tablero!$B$8/100))*(Tablero!$B$7/100) -> 0.033731125 | AX18: =(AL18*(Tablero!$B$10/100)+AM18*(Tablero!$B$11/100)+AN18*(Tablero!$B$12/100)+AO18*(Tablero!$B$13/100)+AP18*(Tablero!$B$14/100))*(Tablero!$B$9/100) -> 0.15277476 | AY18: =(AQ18*(Tablero!$B$16/100)+AR18*(Tablero!$B$17/100)+AS18*(Tablero!$B$18/100))*(Tablero!$B$15/100) -> 0.21705762 | AZ18: =(AT18*(Tablero!$B$20/100)+AU18*(Tablero!$B$21/100))*(Tablero!$B$19/100) -> 0.019000903
B19: 14057 | C19: La Manzanilla de la Paz | D19: 4515 | E19: 44 | F19: 4 | G19: 28.2 | H19: 15.4 | I19: 90.9 | J19: 5 | K19: 0.11 | L19: 25 | M19: 0 | N19: 31.509141 | O19: 7.88 | P19: 4 | Q19: 73.227273 | R19: 31.82 | S19: 31.82 | T19: 70.45 | U19: 68.18 | V19: 160 | W19: 2 | X19: 2 | Y19: 0 | Z19: 0 | AA19: 44.3 | AC19: 52157.1 | AD19: 0.12 | AE19: 45.83 | AF19: 3.02 | AG19: =AV19+AW19+AX19+AY19+AZ19 -> 0.4750896 | AH19: ~ estimación estatal | AI19: =(G19-MIN($G$2:$G$126))/(MAX($G$2:$G$126)-MIN($G$2:$G$126)) -> 0.50938967 | AJ19: =(N19-MIN($N$2:$N$126))/(MAX($N$2:$N$126)-MIN($N$2:$N$126)) -> 0.00066456762 | AK19: =(O19-MIN($O$2:$O$126))/(MAX($O$2:$O$126)-MIN($O$2:$O$126)) -> 0.38382854 | AL19: =(S19-MIN($S$2:$S$126))/(MAX($S$2:$S$126)-MIN($S$2:$S$126)) -> 0.49557728 | AM19: =(T19-MIN($T$2:$T$126))/(MAX($T$2:$T$126)-MIN($T$2:$T$126)) -> 0.73772145 | AN19: =1-(AC19-MIN($AC$2:$AC$126))/(MAX($AC$2:$AC$126)-MIN($AC$2:$AC$126)) -> 0.6258069 | AO19: =(AD19-MIN($AD$2:$AD$126))/(MAX($AD$2:$AD$126)-MIN($AD$2:$AD$126)) -> 0.071856287 | AP19: =1-(AE19-MIN($AE$2:$AE$126))/(MAX($AE$2:$AE$126)-MIN($AE$2:$AE$126)) -> 0.5417 | AQ19: =(V19-MIN($V$2:$V$126))/(MAX($V$2:$V$126)-MIN($V$2:$V$126)) -> 0.44444444 | AR19: =1-(Y19-MIN($Y$2:$Y$126))/(MAX($Y$2:$Y$126)-MIN($Y$2:$Y$126)) -> 1 | AS19: =1-(AA19-MIN($AA$2:$AA$126))/(MAX($AA$2:$AA$126)-MIN($AA$2:$AA$126)) -> 0.68554522 | AT19: =(K19-MIN($K$2:$K$126))/(MAX($K$2:$K$126)-MIN($K$2:$K$126)) -> 0.18181818 | AU19: =(L19-MIN($L$2:$L$126))/(MAX($L$2:$L$126)-MIN($L$2:$L$126)) -> 0.0025970476 | AV19: =(AI19*(Tablero!$B$5/100)+AJ19*(Tablero!$B$6/100))*(Tablero!$B$4/100) -> 0.076474907 | AW19: =(AK19*(Tablero!$B$8/100))*(Tablero!$B$7/100) -> 0.095957136 | AX19: =(AL19*(Tablero!$B$10/100)+AM19*(Tablero!$B$11/100)+AN19*(Tablero!$B$12/100)+AO19*(Tablero!$B$13/100)+AP19*(Tablero!$B$14/100))*(Tablero!$B$9/100) -> 0.1114641 | AY19: =(AQ19*(Tablero!$B$16/100)+AR19*(Tablero!$B$17/100)+AS19*(Tablero!$B$18/100))*(Tablero!$B$15/100) -> 0.18658308 | AZ19: =(AT19*(Tablero!$B$20/100)+AU19*(Tablero!$B$21/100))*(Tablero!$B$19/100) -> 0.0046103807
B20: 14054 | C20: El Limón | D20: 5390 | E20: 80 | F20: 42 | G20: 41 | H20: 129.1 | I20: 47.5 | J20: 16 | K20: 0.2 | L20: 35 | M20: 0 | N20: 45.29262 | O20: 1.97 | P20: 23 | Q20: 74.625 | R20: 51.25 | S20: 46.25 | T20: 46.25 | U20: 51.25 | V20: 215 | W20: 3 | X20: 3 | Y20: 0 | Z20: 0 | AA20: 55.7 | AC20: 52157.1 | AD20: 0.12 | AE20: 45.83 | AF20: 3.02 | AG20: =AV20+AW20+AX20+AY20+AZ20 -> 0.45374697 | AH20: ~ estimación estatal | AI20: =(G20-MIN($G$2:$G$126))/(MAX($G$2:$G$126)-MIN($G$2:$G$126)) -> 0.80985915 | AJ20: =(N20-MIN($N$2:$N$126))/(MAX($N$2:$N$126)-MIN($N$2:$N$126)) -> 0.0009552786 | AK20: =(O20-MIN($O$2:$O$126))/(MAX($O$2:$O$126)-MIN($O$2:$O$126)) -> 0.095957136 | AL20: =(S20-MIN($S$2:$S$126))/(MAX($S$2:$S$126)-MIN($S$2:$S$126)) -> 0.83147114 | AM20: =(T20-MIN($T$2:$T$126))/(MAX($T$2:$T$126)-MIN($T$2:$T$126)) -> 0.38916895 | AN20: =1-(AC20-MIN($AC$2:$AC$126))/(MAX($AC$2:$AC$126)-MIN($AC$2:$AC$126)) -> 0.6258069 | AO20: =(AD20-MIN($AD$2:$AD$126))/(MAX($AD$2:$AD$126)-MIN($AD$2:$AD$126)) -> 0.071856287 | AP20: =1-(AE20-MIN($AE$2:$AE$126))/(MAX($AE$2:$AE$126)-MIN($AE$2:$AE$126)) -> 0.5417 | AQ20: =(V20-MIN($V$2:$V$126))/(MAX($V$2:$V$126)-MIN($V$2:$V$126)) -> 0.59722222 | AR20: =1-(Y20-MIN($Y$2:$Y$126))/(MAX($Y$2:$Y$126)-MIN($Y$2:$Y$126)) -> 1 | AS20: =1-(AA20-MIN($AA$2:$AA$126))/(MAX($AA$2:$AA$126)-MIN($AA$2:$AA$126)) -> 0.58918005 | AT20: =(K20-MIN($K$2:$K$126))/(MAX($K$2:$K$126)-MIN($K$2:$K$126)) -> 0.45454545 | AU20: =(L20-MIN($L$2:$L$126))/(MAX($L$2:$L$126)-MIN($L$2:$L$126)) -> 0.0039639147 | AV20: =(AI20*(Tablero!$B$5/100)+AJ20*(Tablero!$B$6/100))*(Tablero!$B$4/100) -> 0.1215744 | AW20: =(AK20*(Tablero!$B$8/100))*(Tablero!$B$7/100) -> 0.023989284 | AX20: =(AL20*(Tablero!$B$10/100)+AM20*(Tablero!$B$11/100)+AN20*(Tablero!$B$12/100)+AO20*(Tablero!$B$13/100)+AP20*(Tablero!$B$14/100))*(Tablero!$B$9/100) -> 0.097268823 | AY20: =(AQ20*(Tablero!$B$16/100)+AR20*(Tablero!$B$17/100)+AS20*(Tablero!$B$18/100))*(Tablero!$B$15/100) -> 0.19945172 | AZ20: =(AT20*(Tablero!$B$20/100)+AU20*(Tablero!$B$21/100))*(Tablero!$B$19/100) -> 0.011462734
B21: 14113 | C21: San Gabriel | D21: 17388 | E21: 188 | F21: 55 | G21: 30.5 | H21: 53.5 | I21: 70.7 | J21: 30 | K21: 0.16 | L21: 97 | M21: 4 | N21: 206.67502 | O21: 7.13 | P21: 29 | Q21: 70.920213 | R21: 50.53 | S21: 39.89 | T21: 47.34 | U21: 60.64 | V21: 185 | W21: 10 | X21: 10 | Y21: 0 | Z21: 0 | AA21: 57.5 | AB21: 50 | AC21: 53030.07 | AD21: 0.66 | AE21: 30 | AF21: 3.06 | AG21: =AV21+AW21+AX21+AY21+AZ21 -> 0.48535256 | AH21: ✓ datos directos | AI21: =(G21-MIN($G$2:$G$126))/(MAX($G$2:$G$126)-MIN($G$2:$G$126)) -> 0.56338028 | AJ21: =(N21-MIN($N$2:$N$126))/(MAX($N$2:$N$126)-MIN($N$2:$N$126)) -> 0.0043590374 | AK21: =(O21-MIN($O$2:$O$126))/(MAX($O$2:$O$126)-MIN($O$2:$O$126)) -> 0.34729664 | AL21: =(S21-MIN($S$2:$S$126))/(MAX($S$2:$S$126)-MIN($S$2:$S$126)) -> 0.68342644 | AM21: =(T21-MIN($T$2:$T$126))/(MAX($T$2:$T$126)-MIN($T$2:$T$126)) -> 0.40486821 | AN21: =1-(AC21-MIN($AC$2:$AC$126))/(MAX($AC$2:$AC$126)-MIN($AC$2:$AC$126)) -> 0.61691713 | AO21: =(AD21-MIN($AD$2:$AD$126))/(MAX($AD$2:$AD$126)-MIN($AD$2:$AD$126)) -> 0.39520958 | AP21: =1-(AE21-MIN($AE$2:$AE$126))/(MAX($AE$2:$AE$126)-MIN($AE$2:$AE$126)) -> 0.7 | AQ21: =(V21-MIN($V$2:$V$126))/(MAX($V$2:$V$126)-MIN($V$2:$V$126)) -> 0.51388889 | AR21: =1-(Y21-MIN($Y$2:$Y$126))/(MAX($Y$2:$Y$126)-MIN($Y$2:$Y$126)) -> 1 | AS21: =1-(AA21-MIN($AA$2:$AA$126))/(MAX($AA$2:$AA$126)-MIN($AA$2:$AA$126)) -> 0.5739645 | AT21: =(K21-MIN($K$2:$K$126))/(MAX($K$2:$K$126)-MIN($K$2:$K$126)) -> 0.33333333 | AU21: =(L21-MIN($L$2:$L$126))/(MAX($L$2:$L$126)-MIN($L$2:$L$126)) -> 0.012438491 | AV21: =(AI21*(Tablero!$B$5/100)+AJ21*(Tablero!$B$6/100))*(Tablero!$B$4/100) -> 0.084942946 | AW21: =(AK21*(Tablero!$B$8/100))*(Tablero!$B$7/100) -> 0.08682416 | AX21: =(AL21*(Tablero!$B$10/100)+AM21*(Tablero!$B$11/100)+AN21*(Tablero!$B$12/100)+AO21*(Tablero!$B$13/100)+AP21*(Tablero!$B$14/100))*(Tablero!$B$9/100) -> 0.11420316 | AY21: =(AQ21*(Tablero!$B$16/100)+AR21*(Tablero!$B$17/100)+AS21*(Tablero!$B$18/100))*(Tablero!$B$15/100) -> 0.190738 | AZ21: =(AT21*(Tablero!$B$20/100)+AU21*(Tablero!$B$21/100))*(Tablero!$B$19/100) -> 0.0086442956
B22: 14099 | C22: Tolimán | D22: 12028 | E22: 86 | F22: 48 | G22: 20.4 | H22: 68.4 | I22: 44.2 | J22: 12 | K22: 0.14 | L22: 38 | M22: 1 | N22: 297.95672 | O22: 9.31 | P22: 32 | Q22: 71.116279 | R22: 58.14 | S22: 53.49 | T22: 54.65 | U22: 66.28 | V22: 215 | W22: 3 | X22: 3 | Y22: 0 | Z22: 0 | AA22: 24.9 | AC22: 52157.1 | AD22: 0.12 | AE22: 45.83 | AF22: 3.02 | AG22: =AV22+AW22+AX22+AY22+AZ22 -> 0.48372941 | AH22: ~ estimación estatal | AI22: =(G22-MIN($G$2:$G$126))/(MAX($G$2:$G$126)-MIN($G$2:$G$126)) -> 0.32629108 | AJ22: =(N22-MIN($N$2:$N$126))/(MAX($N$2:$N$126)-MIN($N$2:$N$126)) -> 0.0062842838 | AK22: =(O22-MIN($O$2:$O$126))/(MAX($O$2:$O$126)-MIN($O$2:$O$126)) -> 0.45348271 | AL22: =(S22-MIN($S$2:$S$126))/(MAX($S$2:$S$126)-MIN($S$2:$S$126)) -> 1 | AM22: =(T22-MIN($T$2:$T$126))/(MAX($T$2:$T$126)-MIN($T$2:$T$126)) -> 0.51015411 | AN22: =1-(AC22-MIN($AC$2:$AC$126))/(MAX($AC$2:$AC$126)-MIN($AC$2:$AC$126)) -> 0.6258069 | AO22: =(AD22-MIN($AD$2:$AD$126))/(MAX($AD$2:$AD$126)-MIN($AD$2:$AD$126)) -> 0.071856287 | AP22: =1-(AE22-MIN($AE$2:$AE$126))/(MAX($AE$2:$AE$126)-MIN($AE$2:$AE$126)) -> 0.5417 | AQ22: =(V22-MIN($V$2:$V$126))/(MAX($V$2:$V$126)-MIN($V$2:$V$126)) -> 0.59722222 | AR22: =1-(Y22-MIN($Y$2:$Y$126))/(MAX($Y$2:$Y$126)-MIN($Y$2:$Y$126)) -> 1 | AS22: =1-(AA22-MIN($AA$2:$AA$126))/(MAX($AA$2:$AA$126)-MIN($AA$2:$AA$126)) -> 0.84953508 | AT22: =(K22-MIN($K$2:$K$126))/(MAX($K$2:$K$126)-MIN($K$2:$K$126)) -> 0.27272727 | AU22: =(L22-MIN($L$2:$L$126))/(MAX($L$2:$L$126)-MIN($L$2:$L$126)) -> 0.0043739748 | AV22: =(AI22*(Tablero!$B$5/100)+AJ22*(Tablero!$B$6/100))*(Tablero!$B$4/100) -> 0.04957209 | AW22: =(AK22*(Tablero!$B$8/100))*(Tablero!$B$7/100) -> 0.11337068 | AX22: =(AL22*(Tablero!$B$10/100)+AM22*(Tablero!$B$11/100)+AN22*(Tablero!$B$12/100)+AO22*(Tablero!$B$13/100)+AP22*(Tablero!$B$14/100))*(Tablero!$B$9/100) -> 0.10789851 | AY22: =(AQ22*(Tablero!$B$16/100)+AR22*(Tablero!$B$17/100)+AS22*(Tablero!$B$18/100))*(Tablero!$B$15/100) -> 0.2059606 | AZ22: =(AT22*(Tablero!$B$20/100)+AU22*(Tablero!$B$21/100))*(Tablero!$B$19/100) -> 0.0069275312
B23: 14074 | C23: San Julián | D23: 17789 | E23: 152 | F23: 60 | G23: 24.2 | H23: 57.4 | I23: 60.5 | J23: 18 | K23: 0.12 | L23: 70 | M23: 2 | N23: 246.97669 | O23: 6.86 | P23: 36 | Q23: 73.138158 | R23: 42.11 | S23: 40.79 | T23: 78.29 | U23: 66.45 | V23: 185 | W23: 4 | X23: 4 | Y23: 0 | Z23: 0 | AA23: 22.5 | AC23: 52157.1 | AD23: 0.12 | AE23: 45.83 | AF23: 3.02 | AG23: =AV23+AW23+AX23+AY23+AZ23 -> 0.47245256 | AH23: ~ estimación estatal | AI23: =(G23-MIN($G$2:$G$126))/(MAX($G$2:$G$126)-MIN($G$2:$G$126)) -> 0.41549296 | AJ23: =(N23-MIN($N$2:$N$126))/(MAX($N$2:$N$126)-MIN($N$2:$N$126)) -> 0.0052090506 | AK23: =(O23-MIN($O$2:$O$126))/(MAX($O$2:$O$126)-MIN($O$2:$O$126)) -> 0.33414515 | AL23: =(S23-MIN($S$2:$S$126))/(MAX($S$2:$S$126)-MIN($S$2:$S$126)) -> 0.70437616 | AM23: =(T23-MIN($T$2:$T$126))/(MAX($T$2:$T$126)-MIN($T$2:$T$126)) -> 0.85064093 | AN23: =1-(AC23-MIN($AC$2:$AC$126))/(MAX($AC$2:$AC$126)-MIN($AC$2:$AC$126)) -> 0.6258069 | AO23: =(AD23-MIN($AD$2:$AD$126))/(MAX($AD$2:$AD$126)-MIN($AD$2:$AD$126)) -> 0.071856287 | AP23: =1-(AE23-MIN($AE$2:$AE$126))/(MAX($AE$2:$AE$126)-MIN($AE$2:$AE$126)) -> 0.5417 | AQ23: =(V23-MIN($V$2:$V$126))/(MAX($V$2:$V$126)-MIN($V$2:$V$126)) -> 0.51388889 | AR23: =1-(Y23-MIN($Y$2:$Y$126))/(MAX($Y$2:$Y$126)-MIN($Y$2:$Y$126)) -> 1 | AS23: =1-(AA23-MIN($AA$2:$AA$126))/(MAX($AA$2:$AA$126)-MIN($AA$2:$AA$126)) -> 0.86982249 | AT23: =(K23-MIN($K$2:$K$126))/(MAX($K$2:$K$126)-MIN($K$2:$K$126)) -> 0.21212121 | AU23: =(L23-MIN($L$2:$L$126))/(MAX($L$2:$L$126)-MIN($L$2:$L$126)) -> 0.0087479497 | AV23: =(AI23*(Tablero!$B$5/100)+AJ23*(Tablero!$B$6/100))*(Tablero!$B$4/100) -> 0.062844849 | AW23: =(AK23*(Tablero!$B$8/100))*(Tablero!$B$7/100) -> 0.083536288 | AX23: =(AL23*(Tablero!$B$10/100)+AM23*(Tablero!$B$11/100)+AN23*(Tablero!$B$12/100)+AO23*(Tablero!$B$13/100)+AP23*(Tablero!$B$14/100))*(Tablero!$B$9/100) -> 0.12241524 | AY23: =(AQ23*(Tablero!$B$16/100)+AR23*(Tablero!$B$17/100)+AS23*(Tablero!$B$18/100))*(Tablero!$B$15/100) -> 0.19813445 | AZ23: =(AT23*(Tablero!$B$20/100)+AU23*(Tablero!$B$21/100))*(Tablero!$B$19/100) -> 0.005521729
B24: 14038 | C24: Guachinango | D24: 4235 | E24: 50 | F24: 24 | G24: 32.7 | H24: 94.1 | I24: 52 | J24: 6 | K24: 0.12 | L24: 37 | M24: 0 | N24: 82.12492 | O24: 4.32 | P24: 19 | Q24: 77.34 | R24: 44 | S24: 42 | T24: 70 | U24: 76 | V24: 230 | W24: 3 | X24: 3 | Y24: 0 | Z24: 0 | AA24: 70.8 | AB24: 23 | AC24: 36278.85 | AD24: 0.04 | AE24: 52.17 | AF24: 6.44 | AG24: =AV24+AW24+AX24+AY24+AZ24 -> 0.46388729 | AH24: ✓ datos directos | AI24: =(G24-MIN($G$2:$G$126))/(MAX($G$2:$G$126)-MIN($G$2:$G$126)) -> 0.61502347 | AJ24: =(N24-MIN($N$2:$N$126))/(MAX($N$2:$N$126)-MIN($N$2:$N$126)) -> 0.0017321184 | AK24: =(O24-MIN($O$2:$O$126))/(MAX($O$2:$O$126)-MIN($O$2:$O$126)) -> 0.21042377 | AL24: =(S24-MIN($S$2:$S$126))/(MAX($S$2:$S$126)-MIN($S$2:$S$126)) -> 0.7325419 | AM24: =(T24-MIN($T$2:$T$126))/(MAX($T$2:$T$126)-MIN($T$2:$T$126)) -> 0.7312401 | AN24: =1-(AC24-MIN($AC$2:$AC$126))/(MAX($AC$2:$AC$126)-MIN($AC$2:$AC$126)) -> 0.78750103 | AO24: =(AD24-MIN($AD$2:$AD$126))/(MAX($AD$2:$AD$126)-MIN($AD$2:$AD$126)) -> 0.023952096 | AP24: =1-(AE24-MIN($AE$2:$AE$126))/(MAX($AE$2:$AE$126)-MIN($AE$2:$AE$126)) -> 0.4783 | AQ24: =(V24-MIN($V$2:$V$126))/(MAX($V$2:$V$126)-MIN($V$2:$V$126)) -> 0.63888889 | AR24: =1-(Y24-MIN($Y$2:$Y$126))/(MAX($Y$2:$Y$126)-MIN($Y$2:$Y$126)) -> 1 | AS24: =1-(AA24-MIN($AA$2:$AA$126))/(MAX($AA$2:$AA$126)-MIN($AA$2:$AA$126)) -> 0.46153846 | AT24: =(K24-MIN($K$2:$K$126))/(MAX($K$2:$K$126)-MIN($K$2:$K$126)) -> 0.21212121 | AU24: =(L24-MIN($L$2:$L$126))/(MAX($L$2:$L$126)-MIN($L$2:$L$126)) -> 0.0042372881 | AV24: =(AI24*(Tablero!$B$5/100)+AJ24*(Tablero!$B$6/100))*(Tablero!$B$4/100) -> 0.092426733 | AW24: =(AK24*(Tablero!$B$8/100))*(Tablero!$B$7/100) -> 0.052605943 | AX24: =(AL24*(Tablero!$B$10/100)+AM24*(Tablero!$B$11/100)+AN24*(Tablero!$B$12/100)+AO24*(Tablero!$B$13/100)+AP24*(Tablero!$B$14/100))*(Tablero!$B$9/100) -> 0.11301831 | AY24: =(AQ24*(Tablero!$B$16/100)+AR24*(Tablero!$B$17/100)+AS24*(Tablero!$B$18/100))*(Tablero!$B$15/100) -> 0.20042735 | AZ24: =(AT24*(Tablero!$B$20/100)+AU24*(Tablero!$B$21/100))*(Tablero!$B$19/100) -> 0.0054089625
B25: 14107 | C25: Tuxcueca | D25: 7253 | E25: 76 | F25: 21 | G25: 30 | H25: 49.8 | I25: 72.4 | J25: 16 | K25: 0.21 | L25: 28 | M25: 0 | N25: 53.584382 | O25: 6.7 | P25: 8 | Q25: 72.447368 | R25: 43.42 | S25: 18.42 | T25: 59.21 | U25: 57.89 | V25: 135 | W25: 2 | X25: 2 | Y25: 0 | Z25: 0 | AA25: 27.6 | AB25: 24 | AC25: 35070.01 | AD25: 0.62 | AE25: 0 | AF25: 1.53 | AG25: =AV25+AW25+AX25+AY25+AZ25 -> 0.50145606 | AH25: ✓ datos directos | AI25: =(G25-MIN($G$2:$G$126))/(MAX($G$2:$G$126)-MIN($G$2:$G$126)) -> 0.55164319 | AJ25: =(N25-MIN($N$2:$N$126))/(MAX($N$2:$N$126)-MIN($N$2:$N$126)) -> 0.0011301623 | AK25: =(O25-MIN($O$2:$O$126))/(MAX($O$2:$O$126)-MIN($O$2:$O$126)) -> 0.32635168 | AL25: =(S25-MIN($S$2:$S$126))/(MAX($S$2:$S$126)-MIN($S$2:$S$126)) -> 0.18365922 | AM25: =(T25-MIN($T$2:$T$126))/(MAX($T$2:$T$126)-MIN($T$2:$T$126)) -> 0.57583177 | AN25: =1-(AC25-MIN($AC$2:$AC$126))/(MAX($AC$2:$AC$126)-MIN($AC$2:$AC$126)) -> 0.7998111 | AO25: =(AD25-MIN($AD$2:$AD$126))/(MAX($AD$2:$AD$126)-MIN($AD$2:$AD$126)) -> 0.37125749 | AP25: =1-(AE25-MIN($AE$2:$AE$126))/(MAX($AE$2:$AE$126)-MIN($AE$2:$AE$126)) -> 1 | AQ25: =(V25-MIN($V$2:$V$126))/(MAX($V$2:$V$126)-MIN($V$2:$V$126)) -> 0.375 | AR25: =1-(Y25-MIN($Y$2:$Y$126))/(MAX($Y$2:$Y$126)-MIN($Y$2:$Y$126)) -> 1 | AS25: =1-(AA25-MIN($AA$2:$AA$126))/(MAX($AA$2:$AA$126)-MIN($AA$2:$AA$126)) -> 0.82671175 | AT25: =(K25-MIN($K$2:$K$126))/(MAX($K$2:$K$126)-MIN($K$2:$K$126)) -> 0.48484848 | AU25: =(L25-MIN($L$2:$L$126))/(MAX($L$2:$L$126)-MIN($L$2:$L$126)) -> 0.0030071077 | AV25: =(AI25*(Tablero!$B$5/100)+AJ25*(Tablero!$B$6/100))*(Tablero!$B$4/100) -> 0.082859495 | AW25: =(AK25*(Tablero!$B$8/100))*(Tablero!$B$7/100) -> 0.08158792 | AX25: =(AL25*(Tablero!$B$10/100)+AM25*(Tablero!$B$11/100)+AN25*(Tablero!$B$12/100)+AO25*(Tablero!$B$13/100)+AP25*(Tablero!$B$14/100))*(Tablero!$B$9/100) -> 0.14164446 | AY25: =(AQ25*(Tablero!$B$16/100)+AR25*(Tablero!$B$17/100)+AS25*(Tablero!$B$18/100))*(Tablero!$B$15/100) -> 0.18316779 | AZ25: =(AT25*(Tablero!$B$20/100)+AU25*(Tablero!$B$21/100))*(Tablero!$B$19/100) -> 0.01219639
B26: 14081 | C26: Santa María de los Ángeles | D26: 4010 | E26: 33 | F26: 10 | G26: 24.2 | H26: 44 | I26: 69.7 | J26: 4 | K26: 0.12 | L26: 14 | M26: 0 | N26: 28.289044 | O26: 4.71 | P26: 6 | Q26: 74.69697 | R26: 42.42 | S26: 48.48 | T26: 78.79 | U26: 57.58 | V26: 250 | W26: 3 | X26: 3 | Y26: 0 | Z26: 0 | AA26: 74.8 | AB26: 24 | AC26: 29939.9 | AD26: 0.12 | AE26: 45.83 | AF26: 2.29 | AG26: =AV26+AW26+AX26+AY26+AZ26 -> 0.46115899 | AH26: ✓ datos directos | AI26: =(G26-MIN($G$2:$G$126))/(MAX($G$2:$G$126)-MIN($G$2:$G$126)) -> 0.41549296 | AJ26: =(N26-MIN($N$2:$N$126))/(MAX($N$2:$N$126)-MIN($N$2:$N$126)) -> 0.0005966517 | AK26: =(O26-MIN($O$2:$O$126))/(MAX($O$2:$O$126)-MIN($O$2:$O$126)) -> 0.22942036 | AL26: =(S26-MIN($S$2:$S$126))/(MAX($S$2:$S$126)-MIN($S$2:$S$126)) -> 0.88337989 | AM26: =(T26-MIN($T$2:$T$126))/(MAX($T$2:$T$126)-MIN($T$2:$T$126)) -> 0.85784243 | AN26: =1-(AC26-MIN($AC$2:$AC$126))/(MAX($AC$2:$AC$126)-MIN($AC$2:$AC$126)) -> 0.85205292 | AO26: =(AD26-MIN($AD$2:$AD$126))/(MAX($AD$2:$AD$126)-MIN($AD$2:$AD$126)) -> 0.071856287 | AP26: =1-(AE26-MIN($AE$2:$AE$126))/(MAX($AE$2:$AE$126)-MIN($AE$2:$AE$126)) -> 0.5417 | AQ26: =(V26-MIN($V$2:$V$126))/(MAX($V$2:$V$126)-MIN($V$2:$V$126)) -> 0.69444444 | AR26: =1-(Y26-MIN($Y$2:$Y$126))/(MAX($Y$2:$Y$126)-MIN($Y$2:$Y$126)) -> 1 | AS26: =1-(AA26-MIN($AA$2:$AA$126))/(MAX($AA$2:$AA$126)-MIN($AA$2:$AA$126)) -> 0.42772612 | AT26: =(K26-MIN($K$2:$K$126))/(MAX($K$2:$K$126)-MIN($K$2:$K$126)) -> 0.21212121 | AU26: =(L26-MIN($L$2:$L$126))/(MAX($L$2:$L$126)-MIN($L$2:$L$126)) -> 0.0010934937 | AV26: =(AI26*(Tablero!$B$5/100)+AJ26*(Tablero!$B$6/100))*(Tablero!$B$4/100) -> 0.062383609 | AW26: =(AK26*(Tablero!$B$8/100))*(Tablero!$B$7/100) -> 0.05735509 | AX26: =(AL26*(Tablero!$B$10/100)+AM26*(Tablero!$B$11/100)+AN26*(Tablero!$B$12/100)+AO26*(Tablero!$B$13/100)+AP26*(Tablero!$B$14/100))*(Tablero!$B$9/100) -> 0.13095233 | AY26: =(AQ26*(Tablero!$B$16/100)+AR26*(Tablero!$B$17/100)+AS26*(Tablero!$B$18/100))*(Tablero!$B$15/100) -> 0.2051376 | AZ26: =(AT26*(Tablero!$B$20/100)+AU26*(Tablero!$B$21/100))*(Tablero!$B$19/100) -> 0.0053303676
B27: 14004 | C27: Amacueca | D27: 6107 | E27: 63 | F27: 15 | G27: 29.3 | H27: 41.9 | I27: 76.2 | J27: 12 | K27: 0.19 | L27: 29 | M27: 1 | N27: 44.09234 | O27: 4.9 | P27: 9 | Q27: 71.238095 | R27: 47.62 | S27: 47.62 | T27: 66.67 | U27: 52.38 | V27: 105 | W27: 2 | X27: 2 | Y27: 0 | Z27: 0 | AA27: 32.7 | AC27: 52157.1 | AD27: 0.12 | AE27: 45.83 | AF27: 3.02 | AG27: =AV27+AW27+AX27+AY27+AZ27 -> 0.44003799 | AH27: ~ estimación estatal | AI27: =(G27-MIN($G$2:$G$126))/(MAX($G$2:$G$126)-MIN($G$2:$G$126)) -> 0.53521127 | AJ27: =(N27-MIN($N$2:$N$126))/(MAX($N$2:$N$126)-MIN($N$2:$N$126)) -> 0.00092996318 | AK27: =(O27-MIN($O$2:$O$126))/(MAX($O$2:$O$126)-MIN($O$2:$O$126)) -> 0.23867511 | AL27: =(S27-MIN($S$2:$S$126))/(MAX($S$2:$S$126)-MIN($S$2:$S$126)) -> 0.86336127 | AM27: =(T27-MIN($T$2:$T$126))/(MAX($T$2:$T$126)-MIN($T$2:$T$126)) -> 0.68327812 | AN27: =1-(AC27-MIN($AC$2:$AC$126))/(MAX($AC$2:$AC$126)-MIN($AC$2:$AC$126)) -> 0.6258069 | AO27: =(AD27-MIN($AD$2:$AD$126))/(MAX($AD$2:$AD$126)-MIN($AD$2:$AD$126)) -> 0.071856287 | AP27: =1-(AE27-MIN($AE$2:$AE$126))/(MAX($AE$2:$AE$126)-MIN($AE$2:$AE$126)) -> 0.5417 | AQ27: =(V27-MIN($V$2:$V$126))/(MAX($V$2:$V$126)-MIN($V$2:$V$126)) -> 0.29166667 | AR27: =1-(Y27-MIN($Y$2:$Y$126))/(MAX($Y$2:$Y$126)-MIN($Y$2:$Y$126)) -> 1 | AS27: =1-(AA27-MIN($AA$2:$AA$126))/(MAX($AA$2:$AA$126)-MIN($AA$2:$AA$126)) -> 0.78360101 | AT27: =(K27-MIN($K$2:$K$126))/(MAX($K$2:$K$126)-MIN($K$2:$K$126)) -> 0.42424242 | AU27: =(L27-MIN($L$2:$L$126))/(MAX($L$2:$L$126)-MIN($L$2:$L$126)) -> 0.0031437944 | AV27: =(AI27*(Tablero!$B$5/100)+AJ27*(Tablero!$B$6/100))*(Tablero!$B$4/100) -> 0.080374686 | AW27: =(AK27*(Tablero!$B$8/100))*(Tablero!$B$7/100) -> 0.059668777 | AX27: =(AL27*(Tablero!$B$10/100)+AM27*(Tablero!$B$11/100)+AN27*(Tablero!$B$12/100)+AO27*(Tablero!$B$13/100)+AP27*(Tablero!$B$14/100))*(Tablero!$B$9/100) -> 0.11555318 | AY27: =(AQ27*(Tablero!$B$16/100)+AR27*(Tablero!$B$17/100)+AS27*(Tablero!$B$18/100))*(Tablero!$B$15/100) -> 0.17375669 | AZ27: =(AT27*(Tablero!$B$20/100)+AU27*(Tablero!$B$21/100))*(Tablero!$B$19/100) -> 0.010684655
B28: 14090 | C28: Tenamaxtlán | D28: 7605 | E28: 92 | F28: 28 | G28: 34 | H28: 62.1 | I28: 69.6 | J28: 19 | K28: 0.21 | L28: 50 | M28: 1 | N28: 79.891785 | O28: 4.44 | P28: 18 | Q28: 74.597826 | R28: 48.91 | S28: 40.22 | T28: 65.22 | U28: 72.83 | V28: 115 | W28: 4 | X28: 4 | Y28: 0 | Z28: 0 | AA28: 52.6 | AB28: 44 | AC28: 48397.3 | AD28: 0 | AE28: 34.09 | AF28: 6.2 | AG28: =AV28+AW28+AX28+AY28+AZ28 -> 0.45524301 | AH28: ✓ datos directos | AI28: =(G28-MIN($G$2:$G$126))/(MAX($G$2:$G$126)-MIN($G$2:$G$126)) -> 0.64553991 | AJ28: =(N28-MIN($N$2:$N$126))/(MAX($N$2:$N$126)-MIN($N$2:$N$126)) -> 0.0016850187 | AK28: =(O28-MIN($O$2:$O$126))/(MAX($O$2:$O$126)-MIN($O$2:$O$126)) -> 0.21626887 | AL28: =(S28-MIN($S$2:$S$126))/(MAX($S$2:$S$126)-MIN($S$2:$S$126)) -> 0.69110801 | AM28: =(T28-MIN($T$2:$T$126))/(MAX($T$2:$T$126)-MIN($T$2:$T$126)) -> 0.66239378 | AN28: =1-(AC28-MIN($AC$2:$AC$126))/(MAX($AC$2:$AC$126)-MIN($AC$2:$AC$126)) -> 0.66409435 | AO28: =(AD28-MIN($AD$2:$AD$126))/(MAX($AD$2:$AD$126)-MIN($AD$2:$AD$126)) -> 0 | AP28: =1-(AE28-MIN($AE$2:$AE$126))/(MAX($AE$2:$AE$126)-MIN($AE$2:$AE$126)) -> 0.6591 | AQ28: =(V28-MIN($V$2:$V$126))/(MAX($V$2:$V$126)-MIN($V$2:$V$126)) -> 0.31944444 | AR28: =1-(Y28-MIN($Y$2:$Y$126))/(MAX($Y$2:$Y$126)-MIN($Y$2:$Y$126)) -> 1 | AS28: =1-(AA28-MIN($AA$2:$AA$126))/(MAX($AA$2:$AA$126)-MIN($AA$2:$AA$126)) -> 0.61538462 | AT28: =(K28-MIN($K$2:$K$126))/(MAX($K$2:$K$126)-MIN($K$2:$K$126)) -> 0.48484848 | AU28: =(L28-MIN($L$2:$L$126))/(MAX($L$2:$L$126)-MIN($L$2:$L$126)) -> 0.0060142154 | AV28: =(AI28*(Tablero!$B$5/100)+AJ28*(Tablero!$B$6/100))*(Tablero!$B$4/100) -> 0.096999488 | AW28: =(AK28*(Tablero!$B$8/100))*(Tablero!$B$7/100) -> 0.054067219 | AX28: =(AL28*(Tablero!$B$10/100)+AM28*(Tablero!$B$11/100)+AN28*(Tablero!$B$12/100)+AO28*(Tablero!$B$13/100)+AP28*(Tablero!$B$14/100))*(Tablero!$B$9/100) -> 0.11957567 | AY28: =(AQ28*(Tablero!$B$16/100)+AR28*(Tablero!$B$17/100)+AS28*(Tablero!$B$18/100))*(Tablero!$B$15/100) -> 0.17232906 | AZ28: =(AT28*(Tablero!$B$20/100)+AU28*(Tablero!$B$21/100))*(Tablero!$B$19/100) -> 0.012271568
B29: 14027 | C29: Cuautitlán de García Barragán | D29: 18862 | E29: 148 | F29: 59 | G29: 21.9 | H29: 52.4 | I29: 60.1 | J29: 30 | K29: 0.2 | L29: 65 | M29: 1 | N29: 213.50184 | O29: 5.77 | P29: 37 | Q29: 70.783784 | R29: 37.16 | S29: 40.54 | T29: 53.38 | U29: 49.32 | V29: 280 | W29: 8 | X29: 8 | Y29: 0 | Z29: 0 | AA29: 42.4 | AB29: 83 | AC29: 42344.37 | AD29: 0.6 | AE29: 34.94 | AF29: 3.27 | AG29: =AV29+AW29+AX29+AY29+AZ29 -> 0.47405304 | AH29: ✓ datos directos | AI29: =(G29-MIN($G$2:$G$126))/(MAX($G$2:$G$126)-MIN($G$2:$G$126)) -> 0.36150235 | AJ29: =(N29-MIN($N$2:$N$126))/(MAX($N$2:$N$126)-MIN($N$2:$N$126)) -> 0.0045030237 | AK29: =(O29-MIN($O$2:$O$126))/(MAX($O$2:$O$126)-MIN($O$2:$O$126)) -> 0.28105212 | AL29: =(S29-MIN($S$2:$S$126))/(MAX($S$2:$S$126)-MIN($S$2:$S$126)) -> 0.6985568 | AM29: =(T29-MIN($T$2:$T$126))/(MAX($T$2:$T$126)-MIN($T$2:$T$126)) -> 0.49186231 | AN29: =1-(AC29-MIN($AC$2:$AC$126))/(MAX($AC$2:$AC$126)-MIN($AC$2:$AC$126)) -> 0.72573358 | AO29: =(AD29-MIN($AD$2:$AD$126))/(MAX($AD$2:$AD$126)-MIN($AD$2:$AD$126)) -> 0.35928144 | AP29: =1-(AE29-MIN($AE$2:$AE$126))/(MAX($AE$2:$AE$126)-MIN($AE$2:$AE$126)) -> 0.6506 | AQ29: =(V29-MIN($V$2:$V$126))/(MAX($V$2:$V$126)-MIN($V$2:$V$126)) -> 0.77777778 | AR29: =1-(Y29-MIN($Y$2:$Y$126))/(MAX($Y$2:$Y$126)-MIN($Y$2:$Y$126)) -> 1 | AS29: =1-(AA29-MIN($AA$2:$AA$126))/(MAX($AA$2:$AA$126)-MIN($AA$2:$AA$126)) -> 0.70160609 | AT29: =(K29-MIN($K$2:$K$126))/(MAX($K$2:$K$126)-MIN($K$2:$K$126)) -> 0.45454545 | AU29: =(L29-MIN($L$2:$L$126))/(MAX($L$2:$L$126)-MIN($L$2:$L$126)) -> 0.0080645161 | AV29: =(AI29*(Tablero!$B$5/100)+AJ29*(Tablero!$B$6/100))*(Tablero!$B$4/100) -> 0.054675654 | AW29: =(AK29*(Tablero!$B$8/100))*(Tablero!$B$7/100) -> 0.07026303 | AX29: =(AL29*(Tablero!$B$10/100)+AM29*(Tablero!$B$11/100)+AN29*(Tablero!$B$12/100)+AO29*(Tablero!$B$13/100)+AP29*(Tablero!$B$14/100))*(Tablero!$B$9/100) -> 0.11723117 | AY29: =(AQ29*(Tablero!$B$16/100)+AR29*(Tablero!$B$17/100)+AS29*(Tablero!$B$18/100))*(Tablero!$B$15/100) -> 0.22031793 | AZ29: =(AT29*(Tablero!$B$20/100)+AU29*(Tablero!$B$21/100))*(Tablero!$B$19/100) -> 0.011565249
